Workbook

Sheet MATLAB
A1: Class_Label | H1: N/A | I1: =OFFSET(Database!$F114,0,COLUMN(Database!F114)*2-12) -> MGP | J1: =OFFSET(Database!$F114,0,COLUMN(Database!G114)*2-12) -> MGP | K1: =OFFSET(Database!$F114,0,COLUMN(Database!H114)*2-12) -> IMG | L1: =OFFSET(Database!$F114,0,COLUMN(Database!I114)*2-12) -> IMG | M1: =OFFSET(Database!$F114,0,COLUMN(Database!J114)*2-12) -> IMG | N1: =OFFSET(Database!$F114,0,COLUMN(Database!K114)*2-12) -> CR | O1: =OFFSET(Database!$F114,0,COLUMN(Database!L114)*2-12) -> CR | P1: =OFFSET(Database!$F114,0,COLUMN(Database!M114)*2-12) -> CR | ... GP1: =OFFSET(Database!$F114,0,COLUMN(Database!GM114)*2-12) -> ISCS
A2: Class | H2: NaN | I2: =OFFSET(Database!$F115,0,COLUMN(Database!F115)*2-12) -> 0 | J2: =OFFSET(Database!$F115,0,COLUMN(Database!G115)*2-12) -> 0 | K2: =OFFSET(Database!$F115,0,COLUMN(Database!H115)*2-12) -> 0 | L2: =OFFSET(Database!$F115,0,COLUMN(Database!I115)*2-12) -> 0 | M2: =OFFSET(Database!$F115,0,COLUMN(Database!J115)*2-12) -> 0 | N2: =OFFSET(Database!$F115,0,COLUMN(Database!K115)*2-12) -> 0 | O2: =OFFSET(Database!$F115,0,COLUMN(Database!L115)*2-12) -> 0 | P2: =OFFSET(Database!$F115,0,COLUMN(Database!M115)*2-12) -> 0 | ... GP2: =OFFSET(Database!$F115,0,COLUMN(Database!GM115)*2-12) -> 0
A3: Amino_Acid_Label | B3: Amino_Acid | C3: Amine_Position | D3: Chirality | E3: N | F3: Symbol | G3: Pub_chem_ID | H3: Molar_Mass | I3: =OFFSET(Database!$F3,0,COLUMN(Database!F3)*2-12) -> Imilac metal | J3: =OFFSET(Database!$F3,0,COLUMN(Database!G3)*2-12) -> Imilac silicate | K3: =OFFSET(Database!$F3,0,COLUMN(Database!H3)*2-12) -> Canyon Diablo | L3: =OFFSET(Database!$F3,0,COLUMN(Database!I3)*2-12) -> Cape York | M3: =OFFSET(Database!$F3,0,COLUMN(Database!J3)*2-12) -> Campo del Cielo | N3: =OFFSET(Database!$F3,0,COLUMN(Database!K3)*2-12) -> GRO 95577 | O3: =OFFSET(Database!$F3,0,COLUMN(Database!L3)*2-12) -> GRO 95577 | P3: =OFFSET(Database!$F3,0,COLUMN(Database!M3)*2-12) -> MIL 09001 | ... GP3: =OFFSET(Database!$F3,0,COLUMN(Database!GM3)*2-12) -> AA Synthesis-2
A4: =Database!A4 -> Glycine | B4: glycine | C4: =Database!B4 -> ɑ | D4: =Database!C4 -> Achiral | E4: =Database!D4 -> 183 | F4: G | G4: 750 | H4: =Database!E4 -> 75.07 | I4: =OFFSET(Database!$F4,0,COLUMN(Database!F4)*2-12) -> 0.1902 | J4: =OFFSET(Database!$F4,0,COLUMN(Database!G4)*2-12) -> 0.8024 | K4: =OFFSET(Database!$F4,0,COLUMN(Database!H4)*2-12) -> 0.5274 | L4: =OFFSET(Database!$F4,0,COLUMN(Database!I4)*2-12) -> 0.2728 | M4: =OFFSET(Database!$F4,0,COLUMN(Database!J4)*2-12) -> 0.3647 | N4: =OFFSET(Database!$F4,0,COLUMN(Database!K4)*2-12) -> 1.8116425 | O4: =OFFSET(Database!$F4,0,COLUMN(Database!L4)*2-12) -> 3.7 | P4: =OFFSET(Database!$F4,0,COLUMN(Database!M4)*2-12) -> 3.46 | ... GP4: =OFFSET(Database!$F4,0,COLUMN(Database!GM4)*2-12) -> 3836.4193
A5: =Database!A5 -> Taurine | B5: taurine | C5: =Database!B5 -> β | D5: =Database!C5 -> Achiral | E5: =Database!D5 -> 3 | F5: TAU | G5: 1123 | H5: =Database!E5 -> 125.14 | I5: =OFFSET(Database!$F5,0,COLUMN(Database!F5)*2-12) -> n.r. | J5: =OFFSET(Database!$F5,0,COLUMN(Database!G5)*2-12) -> n.r. | K5: =OFFSET(Database!$F5,0,COLUMN(Database!H5)*2-12) -> n.r. | L5: =OFFSET(Database!$F5,0,COLUMN(Database!I5)*2-12) -> n.r. | M5: =OFFSET(Database!$F5,0,COLUMN(Database!J5)*2-12) -> n.r. | N5: =OFFSET(Database!$F5,0,COLUMN(Database!K5)*2-12) -> n.r. | O5: =OFFSET(Database!$F5,0,COLUMN(Database!L5)*2-12) -> n.r. | P5: =OFFSET(Database!$F5,0,COLUMN(Database!M5)*2-12) -> n.r. | ... GP5: =OFFSET(Database!$F5,0,COLUMN(Database!GM5)*2-12) -> n.r.
A6: =Database!A6 -> D-alanine | B6: alanine | C6: =Database!B6 -> ɑ | D6: =Database!C6 -> D | E6: =Database!D6 -> 106 | F6: DA | G6: 71080 | H6: =Database!E6 -> 89.09 | I6: =OFFSET(Database!$F6,0,COLUMN(Database!F6)*2-12) -> 0.0069 | J6: =OFFSET(Database!$F6,0,COLUMN(Database!G6)*2-12) -> 0.0164 | K6: =OFFSET(Database!$F6,0,COLUMN(Database!H6)*2-12) -> 0.0208 | L6: =OFFSET(Database!$F6,0,COLUMN(Database!I6)*2-12) -> 0.0078 | M6: =OFFSET(Database!$F6,0,COLUMN(Database!J6)*2-12) -> 0.009 | N6: =OFFSET(Database!$F6,0,COLUMN(Database!K6)*2-12) -> 0.83062072 | O6: =OFFSET(Database!$F6,0,COLUMN(Database!L6)*2-12) -> 0.52 | P6: =OFFSET(Database!$F6,0,COLUMN(Database!M6)*2-12) -> 0.93 | ... GP6: =OFFSET(Database!$F6,0,COLUMN(Database!GM6)*2-12) -> 1784.7121
A7: =Database!A7 -> L-alanine | B7: alanine | C7: =Database!B7 -> ɑ | D7: =Database!C7 -> L | E7: =Database!D7 -> 116 | F7: LA | G7: 5950 | H7: =Database!E7 -> 89.09 | I7: =OFFSET(Database!$F7,0,COLUMN(Database!F7)*2-12) -> 0.0107 | J7: =OFFSET(Database!$F7,0,COLUMN(Database!G7)*2-12) -> 0.0573 | K7: =OFFSET(Database!$F7,0,COLUMN(Database!H7)*2-12) -> 0.1238 | L7: =OFFSET(Database!$F7,0,COLUMN(Database!I7)*2-12) -> 0.0015 | M7: =OFFSET(Database!$F7,0,COLUMN(Database!J7)*2-12) -> 0.0185 | N7: =OFFSET(Database!$F7,0,COLUMN(Database!K7)*2-12) -> 1.077562 | O7: =OFFSET(Database!$F7,0,COLUMN(Database!L7)*2-12) -> 0.39 | P7: =OFFSET(Database!$F7,0,COLUMN(Database!M7)*2-12) -> 1.06 | ... GP7: =OFFSET(Database!$F7,0,COLUMN(Database!GM7)*2-12) -> 1829.6105
A8: =Database!A8 -> alanine | B8: alanine | C8: =Database!B8 -> ɑ | D8: =Database!C8 -> Both | E8: =Database!D8 -> 56 | F8: A | G8: 71080, 5950 | H8: =Database!E8 -> 89.09 | I8: =OFFSET(Database!$F8,0,COLUMN(Database!F8)*2-12) -> n.r. | J8: =OFFSET(Database!$F8,0,COLUMN(Database!G8)*2-12) -> n.r. | K8: =OFFSET(Database!$F8,0,COLUMN(Database!H8)*2-12) -> n.r. | L8: =OFFSET(Database!$F8,0,COLUMN(Database!I8)*2-12) -> n.r. | M8: =OFFSET(Database!$F8,0,COLUMN(Database!J8)*2-12) -> n.r. | N8: =OFFSET(Database!$F8,0,COLUMN(Database!K8)*2-12) -> n.r. | O8: =OFFSET(Database!$F8,0,COLUMN(Database!L8)*2-12) -> n.r. | P8: =OFFSET(Database!$F8,0,COLUMN(Database!M8)*2-12) -> n.r. | ... GP8: =OFFSET(Database!$F8,0,COLUMN(Database!GM8)*2-12) -> n.r.
A9: =Database!A9 -> β-alanine | B9: beta-alanine | C9: =Database!B9 -> β | D9: =Database!C9 -> Both | E9: =Database!D9 -> 138 | F9: BALA | G9: 239 | H9: =Database!E9 -> 89.09 | I9: =OFFSET(Database!$F9,0,COLUMN(Database!F9)*2-12) -> 0.0537 | J9: =OFFSET(Database!$F9,0,COLUMN(Database!G9)*2-12) -> 0.0821 | K9: =OFFSET(Database!$F9,0,COLUMN(Database!H9)*2-12) -> 0.0565 | L9: =OFFSET(Database!$F9,0,COLUMN(Database!I9)*2-12) -> 0.0428 | M9: =OFFSET(Database!$F9,0,COLUMN(Database!J9)*2-12) -> 0.0374 | N9: =OFFSET(Database!$F9,0,COLUMN(Database!K9)*2-12) -> 1.3694017 | O9: =OFFSET(Database!$F9,0,COLUMN(Database!L9)*2-12) -> 3.3 | P9: =OFFSET(Database!$F9,0,COLUMN(Database!M9)*2-12) -> 3.55 | ... GP9: =OFFSET(Database!$F9,0,COLUMN(Database!GM9)*2-12) -> 2222.4717
A10: =Database!A10 -> Sarcosine | B10: sarcosine | C10: =Database!B10 -> ɑ | D10: =Database!C10 -> Achiral | E10: =Database!D10 -> 1 | F10: SAR | G10: 1088 | H10: =Database!E10 -> 89.09 | I10: =OFFSET(Database!$F10,0,COLUMN(Database!F10)*2-12) -> n.r. | J10: =OFFSET(Database!$F10,0,COLUMN(Database!G10)*2-12) -> n.r. | K10: =OFFSET(Database!$F10,0,COLUMN(Database!H10)*2-12) -> n.r. | L10: =OFFSET(Database!$F10,0,COLUMN(Database!I10)*2-12) -> n.r. | M10: =OFFSET(Database!$F10,0,COLUMN(Database!J10)*2-12) -> n.r. | N10: =OFFSET(Database!$F10,0,COLUMN(Database!K10)*2-12) -> n.r. | O10: =OFFSET(Database!$F10,0,COLUMN(Database!L10)*2-12) -> n.r. | P10: =OFFSET(Database!$F10,0,COLUMN(Database!M10)*2-12) -> n.r. | ... GP10: =OFFSET(Database!$F10,0,COLUMN(Database!GM10)*2-12) -> n.d.
A11: =Database!A11 -> D-serine | B11: serine | C11: =Database!B11 -> ɑ | D11: =Database!C11 -> D | E11: =Database!D11 -> 72 | F11: DS | G11: 71077 | H11: =Database!E11 -> 105.09 | I11: =OFFSET(Database!$F11,0,COLUMN(Database!F11)*2-12) -> 0.002 | J11: =OFFSET(Database!$F11,0,COLUMN(Database!G11)*2-12) -> 0.0146 | K11: =OFFSET(Database!$F11,0,COLUMN(Database!H11)*2-12) -> 0.0017 | L11: =OFFSET(Database!$F11,0,COLUMN(Database!I11)*2-12) -> 0.0015 | M11: =OFFSET(Database!$F11,0,COLUMN(Database!J11)*2-12) -> tr | N11: =OFFSET(Database!$F11,0,COLUMN(Database!K11)*2-12) -> n.r. | O11: =OFFSET(Database!$F11,0,COLUMN(Database!L11)*2-12) -> <0.04 | P11: =OFFSET(Database!$F11,0,COLUMN(Database!M11)*2-12) -> 0.05 | ... GP11: =OFFSET(Database!$F11,0,COLUMN(Database!GM11)*2-12) -> 218.86002
A12: =Database!A12 -> L-serine | B12: serine | C12: =Database!B12 -> ɑ | D12: =Database!C12 -> L | E12: =Database!D12 -> 96 | F12: LS | G12: 5951 | H12: =Database!E12 -> 105.09 | I12: =OFFSET(Database!$F12,0,COLUMN(Database!F12)*2-12) -> 0.0035 | J12: =OFFSET(Database!$F12,0,COLUMN(Database!G12)*2-12) -> 0.1044 | K12: =OFFSET(Database!$F12,0,COLUMN(Database!H12)*2-12) -> 0.0387 | L12: =OFFSET(Database!$F12,0,COLUMN(Database!I12)*2-12) -> 0.0078 | M12: =OFFSET(Database!$F12,0,COLUMN(Database!J12)*2-12) -> n.d. | N12: =OFFSET(Database!$F12,0,COLUMN(Database!K12)*2-12) -> n.r. | O12: =OFFSET(Database!$F12,0,COLUMN(Database!L12)*2-12) -> <0.03 | P12: =OFFSET(Database!$F12,0,COLUMN(Database!M12)*2-12) -> 0.06 | ... GP12: =OFFSET(Database!$F12,0,COLUMN(Database!GM12)*2-12) -> 266.43829
A13: =Database!A13 -> serine | B13: serine | C13: =Database!B13 -> ɑ | D13: =Database!C13 -> Both | E13: =Database!D13 -> 57 | F13: S | G13: 71077, 5951 | H13: =Database!E13 -> 105.09 | I13: =OFFSET(Database!$F13,0,COLUMN(Database!F13)*2-12) -> n.r. | J13: =OFFSET(Database!$F13,0,COLUMN(Database!G13)*2-12) -> n.r. | K13: =OFFSET(Database!$F13,0,COLUMN(Database!H13)*2-12) -> n.r. | L13: =OFFSET(Database!$F13,0,COLUMN(Database!I13)*2-12) -> n.r. | M13: =OFFSET(Database!$F13,0,COLUMN(Database!J13)*2-12) -> n.r. | N13: =OFFSET(Database!$F13,0,COLUMN(Database!K13)*2-12) -> n.r. | O13: =OFFSET(Database!$F13,0,COLUMN(Database!L13)*2-12) -> n.r. | P13: =OFFSET(Database!$F13,0,COLUMN(Database!M13)*2-12) -> n.r. | ... GP13: =OFFSET(Database!$F13,0,COLUMN(Database!GM13)*2-12) -> n.r.
A14: =Database!A14 -> D-cysteine | B14: cysteine | C14: =Database!B14 -> ɑ | D14: =Database!C14 -> D | E14: =Database!D14 -> 0 | F14: DC | G14: 92851 | H14: =Database!E14 -> 121.16 | I14: =OFFSET(Database!$F14,0,COLUMN(Database!F14)*2-12) -> n.r. | J14: =OFFSET(Database!$F14,0,COLUMN(Database!G14)*2-12) -> n.r. | K14: =OFFSET(Database!$F14,0,COLUMN(Database!H14)*2-12) -> n.r. | L14: =OFFSET(Database!$F14,0,COLUMN(Database!I14)*2-12) -> n.r. | M14: =OFFSET(Database!$F14,0,COLUMN(Database!J14)*2-12) -> n.r. | N14: =OFFSET(Database!$F14,0,COLUMN(Database!K14)*2-12) -> n.r. | O14: =OFFSET(Database!$F14,0,COLUMN(Database!L14)*2-12) -> n.r. | P14: =OFFSET(Database!$F14,0,COLUMN(Database!M14)*2-12) -> n.r. | ... GP14: =OFFSET(Database!$F14,0,COLUMN(Database!GM14)*2-12) -> n.r.
A15: =Database!A15 -> L-cysteine | B15: cysteine | C15: =Database!B15 -> ɑ | D15: =Database!C15 -> L | E15: =Database!D15 -> 8 | F15: LC | G15: 5862 | H15: =Database!E15 -> 121.16 | I15: =OFFSET(Database!$F15,0,COLUMN(Database!F15)*2-12) -> n.r. | J15: =OFFSET(Database!$F15,0,COLUMN(Database!G15)*2-12) -> n.r. | K15: =OFFSET(Database!$F15,0,COLUMN(Database!H15)*2-12) -> n.r. | L15: =OFFSET(Database!$F15,0,COLUMN(Database!I15)*2-12) -> n.r. | M15: =OFFSET(Database!$F15,0,COLUMN(Database!J15)*2-12) -> n.r. | N15: =OFFSET(Database!$F15,0,COLUMN(Database!K15)*2-12) -> n.r. | O15: =OFFSET(Database!$F15,0,COLUMN(Database!L15)*2-12) -> n.r. | P15: =OFFSET(Database!$F15,0,COLUMN(Database!M15)*2-12) -> n.r. | ... GP15: =OFFSET(Database!$F15,0,COLUMN(Database!GM15)*2-12) -> n.r.
A16: =Database!A16 -> cysteine | B16: cysteine | C16: =Database!B16 -> ɑ | D16: =Database!C16 -> Both | E16: =Database!D16 -> 19 | F16: C | G16: 92851, 5862 | H16: =Database!E16 -> 121.16 | I16: =OFFSET(Database!$F16,0,COLUMN(Database!F16)*2-12) -> n.r. | J16: =OFFSET(Database!$F16,0,COLUMN(Database!G16)*2-12) -> n.r. | K16: =OFFSET(Database!$F16,0,COLUMN(Database!H16)*2-12) -> n.r. | L16: =OFFSET(Database!$F16,0,COLUMN(Database!I16)*2-12) -> n.r. | M16: =OFFSET(Database!$F16,0,COLUMN(Database!J16)*2-12) -> n.r. | N16: =OFFSET(Database!$F16,0,COLUMN(Database!K16)*2-12) -> n.r. | O16: =OFFSET(Database!$F16,0,COLUMN(Database!L16)*2-12) -> n.r. | P16: =OFFSET(Database!$F16,0,COLUMN(Database!M16)*2-12) -> n.r. | ... GP16: =OFFSET(Database!$F16,0,COLUMN(Database!GM16)*2-12) -> n.r.
A17: =Database!A17 -> D-aspartic acid | B17: aspartic acid | C17: =Database!B17 -> ɑ | D17: =Database!C17 -> D | E17: =Database!D17 -> 92 | F17: DD | G17: 83887 | H17: =Database!E17 -> 133.1 | I17: =OFFSET(Database!$F17,0,COLUMN(Database!F17)*2-12) -> 0.0013 | J17: =OFFSET(Database!$F17,0,COLUMN(Database!G17)*2-12) -> 0.0062 | K17: =OFFSET(Database!$F17,0,COLUMN(Database!H17)*2-12) -> tr | L17: =OFFSET(Database!$F17,0,COLUMN(Database!I17)*2-12) -> 0.0019 | M17: =OFFSET(Database!$F17,0,COLUMN(Database!J17)*2-12) -> tr | N17: =OFFSET(Database!$F17,0,COLUMN(Database!K17)*2-12) -> 0.090157776 | O17: =OFFSET(Database!$F17,0,COLUMN(Database!L17)*2-12) -> <0.06 | P17: =OFFSET(Database!$F17,0,COLUMN(Database!M17)*2-12) -> 0.19 | ... GP17: =OFFSET(Database!$F17,0,COLUMN(Database!GM17)*2-12) -> 9.7670924
A18: =Database!A18 -> L-aspartic acid | B18: aspartic acid | C18: =Database!B18 -> ɑ | D18: =Database!C18 -> L | E18: =Database!D18 -> 103 | F18: LD | G18: 5960 | H18: =Database!E18 -> 133.1 | I18: =OFFSET(Database!$F18,0,COLUMN(Database!F18)*2-12) -> tr | J18: =OFFSET(Database!$F18,0,COLUMN(Database!G18)*2-12) -> 0.0446 | K18: =OFFSET(Database!$F18,0,COLUMN(Database!H18)*2-12) -> 0.0035 | L18: =OFFSET(Database!$F18,0,COLUMN(Database!I18)*2-12) -> 0.0045 | M18: =OFFSET(Database!$F18,0,COLUMN(Database!J18)*2-12) -> bb | N18: =OFFSET(Database!$F18,0,COLUMN(Database!K18)*2-12) -> 0.14274981 | O18: =OFFSET(Database!$F18,0,COLUMN(Database!L18)*2-12) -> <0.02 | P18: =OFFSET(Database!$F18,0,COLUMN(Database!M18)*2-12) -> 0.18 | ... GP18: =OFFSET(Database!$F18,0,COLUMN(Database!GM18)*2-12) -> 18.78287
A19: =Database!A19 -> aspartic acid | B19: aspartic acid | C19: =Database!B19 -> ɑ | D19: =Database!C19 -> Both | E19: =Database!D19 -> 54 | F19: D | G19: 83887, 5960 | H19: =Database!E19 -> 133.1 | I19: =OFFSET(Database!$F19,0,COLUMN(Database!F19)*2-12) -> n.r. | J19: =OFFSET(Database!$F19,0,COLUMN(Database!G19)*2-12) -> n.r. | K19: =OFFSET(Database!$F19,0,COLUMN(Database!H19)*2-12) -> n.r. | L19: =OFFSET(Database!$F19,0,COLUMN(Database!I19)*2-12) -> n.r. | M19: =OFFSET(Database!$F19,0,COLUMN(Database!J19)*2-12) -> n.r. | N19: =OFFSET(Database!$F19,0,COLUMN(Database!K19)*2-12) -> n.r. | O19: =OFFSET(Database!$F19,0,COLUMN(Database!L19)*2-12) -> n.r. | P19: =OFFSET(Database!$F19,0,COLUMN(Database!M19)*2-12) -> n.r. | ... GP19: =OFFSET(Database!$F19,0,COLUMN(Database!GM19)*2-12) -> n.r.
A20: =Database!A20 -> D-threonine | B20: threonine | C20: =Database!B20 -> ɑ | D20: =Database!C20 -> D | E20: =Database!D20 -> 13 | F20: DT | G20: 69435 | H20: =Database!E20 -> 119.12 | I20: =OFFSET(Database!$F20,0,COLUMN(Database!F20)*2-12) -> n.r. | J20: =OFFSET(Database!$F20,0,COLUMN(Database!G20)*2-12) -> n.r. | K20: =OFFSET(Database!$F20,0,COLUMN(Database!H20)*2-12) -> n.r. | L20: =OFFSET(Database!$F20,0,COLUMN(Database!I20)*2-12) -> n.r. | M20: =OFFSET(Database!$F20,0,COLUMN(Database!J20)*2-12) -> n.r. | N20: =OFFSET(Database!$F20,0,COLUMN(Database!K20)*2-12) -> n.r. | O20: =OFFSET(Database!$F20,0,COLUMN(Database!L20)*2-12) -> n.r. | P20: =OFFSET(Database!$F20,0,COLUMN(Database!M20)*2-12) -> <0.01 | ... GP20: =OFFSET(Database!$F20,0,COLUMN(Database!GM20)*2-12) -> n.d.
A21: =Database!A21 -> L-threonine | B21: threonine | C21: =Database!B21 -> ɑ | D21: =Database!C21 -> L | E21: =Database!D21 -> 40 | F21: LT | G21: 6288 | H21: =Database!E21 -> 119.12 | I21: =OFFSET(Database!$F21,0,COLUMN(Database!F21)*2-12) -> n.r. | J21: =OFFSET(Database!$F21,0,COLUMN(Database!G21)*2-12) -> n.r. | K21: =OFFSET(Database!$F21,0,COLUMN(Database!H21)*2-12) -> n.r. | L21: =OFFSET(Database!$F21,0,COLUMN(Database!I21)*2-12) -> n.r. | M21: =OFFSET(Database!$F21,0,COLUMN(Database!J21)*2-12) -> n.r. | N21: =OFFSET(Database!$F21,0,COLUMN(Database!K21)*2-12) -> n.r. | O21: =OFFSET(Database!$F21,0,COLUMN(Database!L21)*2-12) -> n.r. | P21: =OFFSET(Database!$F21,0,COLUMN(Database!M21)*2-12) -> <0.01 | ... GP21: =OFFSET(Database!$F21,0,COLUMN(Database!GM21)*2-12) -> 57.924782
A22: =Database!A22 -> threonine | B22: threonine | C22: =Database!B22 -> ɑ | D22: =Database!C22 -> Both | E22: =Database!D22 -> 51 | F22: T | G22: 69435, 6288 | H22: =Database!E22 -> 119.12 | I22: =OFFSET(Database!$F22,0,COLUMN(Database!F22)*2-12) -> n.r. | J22: =OFFSET(Database!$F22,0,COLUMN(Database!G22)*2-12) -> n.r. | K22: =OFFSET(Database!$F22,0,COLUMN(Database!H22)*2-12) -> n.r. | L22: =OFFSET(Database!$F22,0,COLUMN(Database!I22)*2-12) -> n.r. | M22: =OFFSET(Database!$F22,0,COLUMN(Database!J22)*2-12) -> n.r. | N22: =OFFSET(Database!$F22,0,COLUMN(Database!K22)*2-12) -> n.r. | O22: =OFFSET(Database!$F22,0,COLUMN(Database!L22)*2-12) -> n.r. | P22: =OFFSET(Database!$F22,0,COLUMN(Database!M22)*2-12) -> n.r. | ... GP22: =OFFSET(Database!$F22,0,COLUMN(Database!GM22)*2-12) -> n.r.
A23: =Database!A23 -> isothreonine | B23: isothreonine | C23: =Database!B23 -> β | D23: =Database!C23 -> Both | E23: =Database!D23 -> 3 | F23: IST | G23: 12647 | H23: =Database!E23 -> 119.12 | I23: =OFFSET(Database!$F23,0,COLUMN(Database!F23)*2-12) -> n.r. | J23: =OFFSET(Database!$F23,0,COLUMN(Database!G23)*2-12) -> n.r. | K23: =OFFSET(Database!$F23,0,COLUMN(Database!H23)*2-12) -> n.r. | L23: =OFFSET(Database!$F23,0,COLUMN(Database!I23)*2-12) -> n.r. | M23: =OFFSET(Database!$F23,0,COLUMN(Database!J23)*2-12) -> n.r. | N23: =OFFSET(Database!$F23,0,COLUMN(Database!K23)*2-12) -> n.r. | O23: =OFFSET(Database!$F23,0,COLUMN(Database!L23)*2-12) -> n.r. | P23: =OFFSET(Database!$F23,0,COLUMN(Database!M23)*2-12) -> n.r. | ... GP23: =OFFSET(Database!$F23,0,COLUMN(Database!GM23)*2-12) -> 512.08865
A24: =Database!A24 -> D-allo-threonine | B24: allo-threonine | C24: =Database!B24 -> β | D24: =Database!C24 -> D | E24: =Database!D24 -> 2 | F24: DAT | G24: 90624 | H24: =Database!E24 -> 119.12 | I24: =OFFSET(Database!$F24,0,COLUMN(Database!F24)*2-12) -> n.r. | J24: =OFFSET(Database!$F24,0,COLUMN(Database!G24)*2-12) -> n.r. | K24: =OFFSET(Database!$F24,0,COLUMN(Database!H24)*2-12) -> n.r. | L24: =OFFSET(Database!$F24,0,COLUMN(Database!I24)*2-12) -> n.r. | M24: =OFFSET(Database!$F24,0,COLUMN(Database!J24)*2-12) -> n.r. | N24: =OFFSET(Database!$F24,0,COLUMN(Database!K24)*2-12) -> n.r. | O24: =OFFSET(Database!$F24,0,COLUMN(Database!L24)*2-12) -> n.r. | P24: =OFFSET(Database!$F24,0,COLUMN(Database!M24)*2-12) -> n.r. | ... GP24: =OFFSET(Database!$F24,0,COLUMN(Database!GM24)*2-12) -> 352.58563
A25: =Database!A25 -> L-allo-threonine | B25: allo-threonine | C25: =Database!B25 -> β | D25: =Database!C25 -> L | E25: =Database!D25 -> 2 | F25: LAT | G25: 99289 | H25: =Database!E25 -> 119.12 | I25: =OFFSET(Database!$F25,0,COLUMN(Database!F25)*2-12) -> n.r. | J25: =OFFSET(Database!$F25,0,COLUMN(Database!G25)*2-12) -> n.r. | K25: =OFFSET(Database!$F25,0,COLUMN(Database!H25)*2-12) -> n.r. | L25: =OFFSET(Database!$F25,0,COLUMN(Database!I25)*2-12) -> n.r. | M25: =OFFSET(Database!$F25,0,COLUMN(Database!J25)*2-12) -> n.r. | N25: =OFFSET(Database!$F25,0,COLUMN(Database!K25)*2-12) -> n.r. | O25: =OFFSET(Database!$F25,0,COLUMN(Database!L25)*2-12) -> n.r. | P25: =OFFSET(Database!$F25,0,COLUMN(Database!M25)*2-12) -> n.r. | ... GP25: =OFFSET(Database!$F25,0,COLUMN(Database!GM25)*2-12) -> 394.56011
A26: =Database!A26 -> D-ɑ-aminobutyric acid | B26: aba | C26: =Database!B26 -> ɑ | D26: =Database!C26 -> D | E26: =Database!D26 -> 3 | F26: DABA | G26: 439691 | H26: =Database!E26 -> 103.12 | I26: =OFFSET(Database!$F26,0,COLUMN(Database!F26)*2-12) -> n.r. | J26: =OFFSET(Database!$F26,0,COLUMN(Database!G26)*2-12) -> n.r. | K26: =OFFSET(Database!$F26,0,COLUMN(Database!H26)*2-12) -> n.r. | L26: =OFFSET(Database!$F26,0,COLUMN(Database!I26)*2-12) -> n.r. | M26: =OFFSET(Database!$F26,0,COLUMN(Database!J26)*2-12) -> n.r. | N26: =OFFSET(Database!$F26,0,COLUMN(Database!K26)*2-12) -> n.r. | O26: =OFFSET(Database!$F26,0,COLUMN(Database!L26)*2-12) -> n.r. | P26: =OFFSET(Database!$F26,0,COLUMN(Database!M26)*2-12) -> n.r. | ... GP26: =OFFSET(Database!$F26,0,COLUMN(Database!GM26)*2-12) -> 610.93871
A27: =Database!A27 -> L-ɑ-aminobutyric acid | B27: aba | C27: =Database!B27 -> ɑ | D27: =Database!C27 -> L | E27: =Database!D27 -> 3 | F27: LABA | G27: 80283 | H27: =Database!E27 -> 103.12 | I27: =OFFSET(Database!$F27,0,COLUMN(Database!F27)*2-12) -> n.r. | J27: =OFFSET(Database!$F27,0,COLUMN(Database!G27)*2-12) -> n.r. | K27: =OFFSET(Database!$F27,0,COLUMN(Database!H27)*2-12) -> n.r. | L27: =OFFSET(Database!$F27,0,COLUMN(Database!I27)*2-12) -> n.r. | M27: =OFFSET(Database!$F27,0,COLUMN(Database!J27)*2-12) -> n.r. | N27: =OFFSET(Database!$F27,0,COLUMN(Database!K27)*2-12) -> n.r. | O27: =OFFSET(Database!$F27,0,COLUMN(Database!L27)*2-12) -> n.r. | P27: =OFFSET(Database!$F27,0,COLUMN(Database!M27)*2-12) -> n.r. | ... GP27: =OFFSET(Database!$F27,0,COLUMN(Database!GM27)*2-12) -> 601.24127
A28: =Database!A28 -> ɑ-aminobutyric acid | B28: aba | C28: =Database!B28 -> ɑ | D28: =Database!C28 -> Both | E28: =Database!D28 -> 60 | F28: ABA | G28: 439691, 80283 | H28: =Database!E28 -> 103.12 | I28: =OFFSET(Database!$F28,0,COLUMN(Database!F28)*2-12) -> 0.0018 | J28: =OFFSET(Database!$F28,0,COLUMN(Database!G28)*2-12) -> tr | K28: =OFFSET(Database!$F28,0,COLUMN(Database!H28)*2-12) -> 0.0023 | L28: =OFFSET(Database!$F28,0,COLUMN(Database!I28)*2-12) -> 0.0016 | M28: =OFFSET(Database!$F28,0,COLUMN(Database!J28)*2-12) -> 0.003 | N28: =OFFSET(Database!$F28,0,COLUMN(Database!K28)*2-12) -> n.r. | O28: =OFFSET(Database!$F28,0,COLUMN(Database!L28)*2-12) -> 0.44 | P28: =OFFSET(Database!$F28,0,COLUMN(Database!M28)*2-12) -> 0.63 | ... GP28: =OFFSET(Database!$F28,0,COLUMN(Database!GM28)*2-12) -> n.r.
A29: =Database!A29 -> D-β-aminobutyric acid | B29: baba | C29: =Database!B29 -> β | D29: =Database!C29 -> D | E29: =Database!D29 -> 65 | F29: DBABA | G29: 5706670 | H29: =Database!E29 -> 103.12 | I29: =OFFSET(Database!$F29,0,COLUMN(Database!F29)*2-12) -> 0.0012 | J29: =OFFSET(Database!$F29,0,COLUMN(Database!G29)*2-12) -> 0.0051 | K29: =OFFSET(Database!$F29,0,COLUMN(Database!H29)*2-12) -> 0.0048 | L29: =OFFSET(Database!$F29,0,COLUMN(Database!I29)*2-12) -> 0.0027 | M29: =OFFSET(Database!$F29,0,COLUMN(Database!J29)*2-12) -> 0.0029 | N29: =OFFSET(Database!$F29,0,COLUMN(Database!K29)*2-12) -> n.r. | O29: =OFFSET(Database!$F29,0,COLUMN(Database!L29)*2-12) -> 0.68 | P29: =OFFSET(Database!$F29,0,COLUMN(Database!M29)*2-12) -> 0.76 | ... GP29: =OFFSET(Database!$F29,0,COLUMN(Database!GM29)*2-12) -> 436.38479
A30: =Database!A30 -> L-β-aminobutyric acid | B30: baba | C30: =Database!B30 -> β | D30: =Database!C30 -> L | E30: =Database!D30 -> 65 | F30: LBABA | G30: 5706671 | H30: =Database!E30 -> 103.12 | I30: =OFFSET(Database!$F30,0,COLUMN(Database!F30)*2-12) -> 0.0012 | J30: =OFFSET(Database!$F30,0,COLUMN(Database!G30)*2-12) -> 0.0052 | K30: =OFFSET(Database!$F30,0,COLUMN(Database!H30)*2-12) -> 0.0047 | L30: =OFFSET(Database!$F30,0,COLUMN(Database!I30)*2-12) -> 0.0027 | M30: =OFFSET(Database!$F30,0,COLUMN(Database!J30)*2-12) -> 0.0029 | N30: =OFFSET(Database!$F30,0,COLUMN(Database!K30)*2-12) -> n.r. | O30: =OFFSET(Database!$F30,0,COLUMN(Database!L30)*2-12) -> 0.58 | P30: =OFFSET(Database!$F30,0,COLUMN(Database!M30)*2-12) -> 0.75 | ... GP30: =OFFSET(Database!$F30,0,COLUMN(Database!GM30)*2-12) -> 397.59503
A31: =Database!A31 -> β-aminobutyric acid | B31: baba | C31: =Database!B31 -> β | D31: =Database!C31 -> Both | E31: =Database!D31 -> 5 | F31: BABA | G31: 5706670, 5706671 | H31: =Database!E31 -> 103.12 | I31: =OFFSET(Database!$F31,0,COLUMN(Database!F31)*2-12) -> n.r. | J31: =OFFSET(Database!$F31,0,COLUMN(Database!G31)*2-12) -> n.r. | K31: =OFFSET(Database!$F31,0,COLUMN(Database!H31)*2-12) -> n.r. | L31: =OFFSET(Database!$F31,0,COLUMN(Database!I31)*2-12) -> n.r. | M31: =OFFSET(Database!$F31,0,COLUMN(Database!J31)*2-12) -> n.r. | N31: =OFFSET(Database!$F31,0,COLUMN(Database!K31)*2-12) -> 0.47517455 | O31: =OFFSET(Database!$F31,0,COLUMN(Database!L31)*2-12) -> n.r. | P31: =OFFSET(Database!$F31,0,COLUMN(Database!M31)*2-12) -> n.r. | ... GP31: =OFFSET(Database!$F31,0,COLUMN(Database!GM31)*2-12) -> n.r.
A32: =Database!A32 -> ɣ-aminobutyric acid | B32: gaba | C32: =Database!B32 -> ɣ | D32: =Database!C32 -> Both | E32: =Database!D32 -> 108 | F32: GABA | G32: 119 | H32: =Database!E32 -> 103.12 | I32: =OFFSET(Database!$F32,0,COLUMN(Database!F32)*2-12) -> n.s. | J32: =OFFSET(Database!$F32,0,COLUMN(Database!G32)*2-12) -> n.s. | K32: =OFFSET(Database!$F32,0,COLUMN(Database!H32)*2-12) -> n.s. | L32: =OFFSET(Database!$F32,0,COLUMN(Database!I32)*2-12) -> n.s. | M32: =OFFSET(Database!$F32,0,COLUMN(Database!J32)*2-12) -> n.s. | N32: =OFFSET(Database!$F32,0,COLUMN(Database!K32)*2-12) -> 0.52366175 | O32: =OFFSET(Database!$F32,0,COLUMN(Database!L32)*2-12) -> 1.4 | P32: =OFFSET(Database!$F32,0,COLUMN(Database!M32)*2-12) -> 1.09 | ... GP32: =OFFSET(Database!$F32,0,COLUMN(Database!GM32)*2-12) -> tr.
A33: =Database!A33 -> ɑ-aminoisobutyric acid | B33: aiba | C33: =Database!B33 -> ɑ | D33: =Database!C33 -> Both | E33: =Database!D33 -> 73 | F33: AIBA | G33: 6119 | H33: =Database!E33 -> 103.12 | I33: =OFFSET(Database!$F33,0,COLUMN(Database!F33)*2-12) -> 0.0155 | J33: =OFFSET(Database!$F33,0,COLUMN(Database!G33)*2-12) -> 0.0135 | K33: =OFFSET(Database!$F33,0,COLUMN(Database!H33)*2-12) -> 0.0177 | L33: =OFFSET(Database!$F33,0,COLUMN(Database!I33)*2-12) -> 0.0159 | M33: =OFFSET(Database!$F33,0,COLUMN(Database!J33)*2-12) -> 0.0092 | N33: =OFFSET(Database!$F33,0,COLUMN(Database!K33)*2-12) -> 0.46547711 | O33: =OFFSET(Database!$F33,0,COLUMN(Database!L33)*2-12) -> 1.7 | P33: =OFFSET(Database!$F33,0,COLUMN(Database!M33)*2-12) -> 1.26 | ... GP33: =OFFSET(Database!$F33,0,COLUMN(Database!GM33)*2-12) -> n.d.
A34: =Database!A34 -> D-β-aminoisobutyric acid | B34: baiba | C34: =Database!B34 -> β | D34: =Database!C34 -> D | E34: =Database!D34 -> 5 | F34: DBAIBA | G34: 439433 | H34: =Database!E34 -> 103.12 | I34: =OFFSET(Database!$F34,0,COLUMN(Database!F34)*2-12) -> n.r. | J34: =OFFSET(Database!$F34,0,COLUMN(Database!G34)*2-12) -> n.r. | K34: =OFFSET(Database!$F34,0,COLUMN(Database!H34)*2-12) -> n.r. | L34: =OFFSET(Database!$F34,0,COLUMN(Database!I34)*2-12) -> n.r. | M34: =OFFSET(Database!$F34,0,COLUMN(Database!J34)*2-12) -> n.r. | N34: =OFFSET(Database!$F34,0,COLUMN(Database!K34)*2-12) -> n.r. | O34: =OFFSET(Database!$F34,0,COLUMN(Database!L34)*2-12) -> n.r. | P34: =OFFSET(Database!$F34,0,COLUMN(Database!M34)*2-12) -> n.r. | ... GP34: =OFFSET(Database!$F34,0,COLUMN(Database!GM34)*2-12) -> 155.15904
A35: =Database!A35 -> L-β-aminoisobutyric acid | B35: baiba | C35: =Database!B35 -> β | D35: =Database!C35 -> L | E35: =Database!D35 -> 5 | F35: LBAIBA | G35: 439434 | H35: =Database!E35 -> 103.12 | I35: =OFFSET(Database!$F35,0,COLUMN(Database!F35)*2-12) -> n.r. | J35: =OFFSET(Database!$F35,0,COLUMN(Database!G35)*2-12) -> n.r. | K35: =OFFSET(Database!$F35,0,COLUMN(Database!H35)*2-12) -> n.r. | L35: =OFFSET(Database!$F35,0,COLUMN(Database!I35)*2-12) -> n.r. | M35: =OFFSET(Database!$F35,0,COLUMN(Database!J35)*2-12) -> n.r. | N35: =OFFSET(Database!$F35,0,COLUMN(Database!K35)*2-12) -> n.r. | O35: =OFFSET(Database!$F35,0,COLUMN(Database!L35)*2-12) -> n.r. | P35: =OFFSET(Database!$F35,0,COLUMN(Database!M35)*2-12) -> n.r. | ... GP35: =OFFSET(Database!$F35,0,COLUMN(Database!GM35)*2-12) -> 145.4616
A36: =Database!A36 -> β-aminoisobutyric acid | B36: baiba | C36: =Database!B36 -> β | D36: =Database!C36 -> Both | E36: =Database!D36 -> 26 | F36: BAIBA | G36: 439433, 439434 | H36: =Database!E36 -> 103.12 | I36: =OFFSET(Database!$F36,0,COLUMN(Database!F36)*2-12) -> n.s. | J36: =OFFSET(Database!$F36,0,COLUMN(Database!G36)*2-12) -> n.s. | K36: =OFFSET(Database!$F36,0,COLUMN(Database!H36)*2-12) -> n.s. | L36: =OFFSET(Database!$F36,0,COLUMN(Database!I36)*2-12) -> n.s. | M36: =OFFSET(Database!$F36,0,COLUMN(Database!J36)*2-12) -> n.s. | N36: =OFFSET(Database!$F36,0,COLUMN(Database!K36)*2-12) -> 0.2909232 | O36: =OFFSET(Database!$F36,0,COLUMN(Database!L36)*2-12) -> n.r. | P36: =OFFSET(Database!$F36,0,COLUMN(Database!M36)*2-12) -> 2.81 | ... GP36: =OFFSET(Database!$F36,0,COLUMN(Database!GM36)*2-12) -> n.r.
A37: =Database!A37 -> 1-Aminocyclopropane-1-carboxylic acid | B37: acpa | C37: =Database!B37 -> ɑ | D37: =Database!C37 -> Achiral | E37: =Database!D37 -> 12 | F37: ACP | G37: 535 | H37: =Database!E37 -> 101.1 | I37: =OFFSET(Database!$F37,0,COLUMN(Database!F37)*2-12) -> n.r. | J37: =OFFSET(Database!$F37,0,COLUMN(Database!G37)*2-12) -> n.r. | K37: =OFFSET(Database!$F37,0,COLUMN(Database!H37)*2-12) -> n.r. | L37: =OFFSET(Database!$F37,0,COLUMN(Database!I37)*2-12) -> n.r. | M37: =OFFSET(Database!$F37,0,COLUMN(Database!J37)*2-12) -> n.r. | N37: =OFFSET(Database!$F37,0,COLUMN(Database!K37)*2-12) -> n.r. | O37: =OFFSET(Database!$F37,0,COLUMN(Database!L37)*2-12) -> n.r. | P37: =OFFSET(Database!$F37,0,COLUMN(Database!M37)*2-12) -> n.r. | ... GP37: =OFFSET(Database!$F37,0,COLUMN(Database!GM37)*2-12) -> n.r.
A38: =Database!A38 -> 4-Amino-2-hydroxybutyric acid | B38: 4-ahba-2 | C38: =Database!B38 -> ɣ | D38: =Database!C38 -> Both | E38: =Database!D38 -> 3 | F38: IIHBA | G38: 26062 | H38: =Database!E38 -> 119.12 | I38: =OFFSET(Database!$F38,0,COLUMN(Database!F38)*2-12) -> n.r. | J38: =OFFSET(Database!$F38,0,COLUMN(Database!G38)*2-12) -> n.r. | K38: =OFFSET(Database!$F38,0,COLUMN(Database!H38)*2-12) -> n.r. | L38: =OFFSET(Database!$F38,0,COLUMN(Database!I38)*2-12) -> n.r. | M38: =OFFSET(Database!$F38,0,COLUMN(Database!J38)*2-12) -> n.r. | N38: =OFFSET(Database!$F38,0,COLUMN(Database!K38)*2-12) -> n.r. | O38: =OFFSET(Database!$F38,0,COLUMN(Database!L38)*2-12) -> n.r. | P38: =OFFSET(Database!$F38,0,COLUMN(Database!M38)*2-12) -> n.r. | ... GP38: =OFFSET(Database!$F38,0,COLUMN(Database!GM38)*2-12) -> 176.29281
A39: =Database!A39 -> D-4-Amino-3-hydroxybutyric acid | B39: 4-ahba-3 | C39: =Database!B39 -> ɣ | D39: =Database!C39 -> D | E39: =Database!D39 -> 1 | F39: DIIIHBA | G39: 2733883 | H39: =Database!E39 -> 119.12 | I39: =OFFSET(Database!$F39,0,COLUMN(Database!F39)*2-12) -> n.r. | J39: =OFFSET(Database!$F39,0,COLUMN(Database!G39)*2-12) -> n.r. | K39: =OFFSET(Database!$F39,0,COLUMN(Database!H39)*2-12) -> n.r. | L39: =OFFSET(Database!$F39,0,COLUMN(Database!I39)*2-12) -> n.r. | M39: =OFFSET(Database!$F39,0,COLUMN(Database!J39)*2-12) -> n.r. | N39: =OFFSET(Database!$F39,0,COLUMN(Database!K39)*2-12) -> n.r. | O39: =OFFSET(Database!$F39,0,COLUMN(Database!L39)*2-12) -> n.r. | P39: =OFFSET(Database!$F39,0,COLUMN(Database!M39)*2-12) -> n.r. | ... GP39: =OFFSET(Database!$F39,0,COLUMN(Database!GM39)*2-12) -> n.d.
A40: =Database!A40 -> L-4-Amino-3-hydroxybutyric acid | B40: 4-ahba-3 | C40: =Database!B40 -> ɣ | D40: =Database!C40 -> L | E40: =Database!D40 -> 1 | F40: LIIIHBA | G40: 6971281 | H40: =Database!E40 -> 119.12 | I40: =OFFSET(Database!$F40,0,COLUMN(Database!F40)*2-12) -> n.r. | J40: =OFFSET(Database!$F40,0,COLUMN(Database!G40)*2-12) -> n.r. | K40: =OFFSET(Database!$F40,0,COLUMN(Database!H40)*2-12) -> n.r. | L40: =OFFSET(Database!$F40,0,COLUMN(Database!I40)*2-12) -> n.r. | M40: =OFFSET(Database!$F40,0,COLUMN(Database!J40)*2-12) -> n.r. | N40: =OFFSET(Database!$F40,0,COLUMN(Database!K40)*2-12) -> n.r. | O40: =OFFSET(Database!$F40,0,COLUMN(Database!L40)*2-12) -> n.r. | P40: =OFFSET(Database!$F40,0,COLUMN(Database!M40)*2-12) -> n.r. | ... GP40: =OFFSET(Database!$F40,0,COLUMN(Database!GM40)*2-12) -> n.d.
...

Sheet MATLAB_Distributions
A1: ID | B1: Category | C1: Subcategory | D1: Experimental conditions | E1: glycine | F1: taurine | G1: D-alanine | H1: L-alanine | I1: alanine | J1: β-alanine | K1: sarcosine | L1: D-serine | M1: L-serine | N1: serine | O1: isoserine | P1: D-cysteine | Q1: L-cysteine | R1: cysteine | S1: D-aspartic acid | T1: L-aspartic acid | U1: aspartic acid | V1: β-OH-Asp | W1: D-threonine | X1: L-threonine | Y1: threonine | Z1: isothreonine | AA1: D-allo-threonine | AB1: L-allo-threonine | AC1: allo-threonine | AD1: D-ɑ-ABA | AE1: L-ɑ-ABA | AF1: ɑ-ABA | AG1: D-βABA | AH1: L-βABA | AI1: βABA | AJ1: GABA | AK1: ɑ-AIB | AL1: D-βAIB | AM1: L-βAIB | AN1: βAIB | AO1: ACPA | AP1: 4-ahba-2 | AQ1: D-4-ahba-3 | AR1: L-4-ahba-3 | AS1: 2-Me-Ser | AT1: D-homoserine | AU1: L-homoserine | AV1: homoserine | AW1: β-homoserine | AX1: ahmpa | AY1: L-asparagine | AZ1: asparagine | BA1: S-methylcys | BB1: homocysteic acid | BC1: D-valine | BD1: L-valine | BE1: valine | BF1: D-isovaline | BG1: L-isovaline | BH1: isovaline | BI1: D-norvaline | BJ1: L-norvaline | BK1: norvaline | BL1: D-3-apa | BM1: L-3-apa | BN1: 3-apa | BO1: 3-amba-3 | BP1: 2-dpa | BQ1: D-4-apa | BR1: L-4-apa | BS1: 4-apa | BT1: 4-amba-2 | BU1: 4-amba-3 | BV1: 5-apa | BW1: D-glutamic acid | BX1: L-glutamic acid | BY1: glutamic acid | BZ1: L-proline | CA1: proline | CB1: trans-4-pro | CC1: D-methionine | CD1: L-methionine | CE1: methionine | CF1: met sulfoxide | CG1: met sulfone | CH1: D-glutamine | CI1: L-glutamine | CJ1: glutamine | CK1: ornithine | CL1: D-β-amsa | CM1: L-β-amsa | CN1: β-amsa | CO1: D-ɑ-AAA | CP1: L-ɑ-AAA | CQ1: ɑ-AAA | CR1: pipeloic acid | CS1: trans-5-pipe | CT1: εaca | CU1: D-leucine | CV1: L-leucine | CW1: leucine | CX1: D-isoleucine | CY1: L-isoleucine | CZ1: isoleucine | DA1: allo-isoleucine | DB1: D-lysine | DC1: L-lysine | DD1: lysine | DE1: 5-hydroxylysine | DF1: 2-Me-Glu | DG1: L-histidine | DH1: histidine | DI1: D-arginine | DJ1: L-arginine | DK1: arginine | DL1: D-phenylalanine | DM1: L-phenylalanine | DN1: phenylalanine | DO1: D-tyrosine | DP1: L-tyrosine | DQ1: tyrosine | DR1: D-tryptophan | DS1: L-tryptophan | DT1: tryptophan | DU1: Ref.
A2: HE-SD1 | B2: Hadean Earth | C2: Classic Experiment | D2: Miller spark discharge apparatus, CH4 (200 torr), NH3 (200 torr), H2 (100 torr), 500 mL H2O | E2: 1 | F2: 4 | G2: 1 | H2: 1 | I2: 4 | J2: 1 | K2: 4 | L2: 1 | M2: 1 | N2: 4 | O2: 2 | P2: 4 | Q2: 4 | R2: 4 | S2: 4 | T2: 4 | U2: 1 | V2: 2 | W2: 4 | X2: 4 | Y2: 4 | Z2: 4 | AA2: 4 | AB2: 4 | AC2: 4 | AD2: 4 | AE2: 4 | AF2: 1 | AG2: 1 | AH2: 1 | AI2: 4 | AJ2: 1 | AK2: 1 | AL2: 1 | AM2: 1 | AN2: 4 | AO2: 4 | AP2: 4 | AQ2: 4 | AR2: 4 | AS2: 2 | AT2: 4 | AU2: 4 | AV2: 2 | AW2: 4 | AX2: 4 | AY2: 4 | AZ2: 4 | BA2: 4 | BB2: 4 | BC2: 4 | BD2: 4 | BE2: 1 | BF2: 1 | BG2: 1 | BH2: 4 | BI2: 4 | BJ2: 4 | BK2: 1 | BL2: 4 | BM2: 4 | BN2: 4 | BO2: 4 | BP2: 4 | BQ2: 4 | BR2: 4 | BS2: 4 | BT2: 4 | BU2: 4 | BV2: 4 | BW2: 1 | BX2: 1 | BY2: 4 | BZ2: 4 | CA2: 4 | CB2: 4 | CC2: 4 | CD2: 4 | CE2: 4 | CF2: 4 | CG2: 4 | CH2: 4 | CI2: 4 | CJ2: 4 | CK2: 2 | CL2: 4 | CM2: 4 | CN2: 4 | CO2: 4 | CP2: 4 | CQ2: 2 | CR2: 4 | CS2: 4 | CT2: 4 | CU2: 4 | CV2: 4 | CW2: 4 | CX2: 4 | CY2: 4 | CZ2: 4 | DA2: 4 | DB2: 4 | DC2: 4 | DD2: 4 | DE2: 4 | DF2: 2 | DG2: 4 | DH2: 4 | DI2: 4 | DJ2: 4 | DK2: 4 | DL2: 4 | DM2: 4 | DN2: 2 | DO2: 4 | DP2: 4 | DQ2: 4 | DR2: 4 | DS2: 4 | DT2: 4 | DU2: Johnson et al. 2008
A3: HE-SD2 | B3: Hadean Earth | C3: Volcanic Experiment | D3: Miller spark discharge apparatus + aspirating nozzle, CH4 (200 torr), NH3 (200 torr), H2 (100 torr), 500 mL H2O | E3: 1 | F3: 4 | G3: 1 | H3: 1 | I3: 4 | J3: 1 | K3: 4 | L3: 1 | M3: 1 | N3: 4 | O3: 1 | P3: 4 | Q3: 4 | R3: 4 | S3: 4 | T3: 4 | U3: 1 | V3: 1 | W3: 4 | X3: 4 | Y3: 4 | Z3: 4 | AA3: 4 | AB3: 4 | AC3: 4 | AD3: 4 | AE3: 4 | AF3: 1 | AG3: 1 | AH3: 1 | AI3: 4 | AJ3: 1 | AK3: 1 | AL3: 1 | AM3: 1 | AN3: 4 | AO3: 4 | AP3: 4 | AQ3: 4 | AR3: 4 | AS3: 1 | AT3: 4 | AU3: 4 | AV3: 1 | AW3: 4 | AX3: 4 | AY3: 4 | AZ3: 4 | BA3: 4 | BB3: 4 | BC3: 4 | BD3: 4 | BE3: 1 | BF3: 1 | BG3: 1 | BH3: 4 | BI3: 4 | BJ3: 4 | BK3: 1 | BL3: 4 | BM3: 4 | BN3: 4 | BO3: 4 | BP3: 4 | BQ3: 4 | BR3: 4 | BS3: 4 | BT3: 4 | BU3: 4 | BV3: 4 | BW3: 1 | BX3: 1 | BY3: 4 | BZ3: 4 | CA3: 4 | CB3: 4 | CC3: 4 | CD3: 4 | CE3: 4 | CF3: 4 | CG3: 4 | CH3: 4 | CI3: 4 | CJ3: 4 | CK3: 1 | CL3: 4 | CM3: 4 | CN3: 4 | CO3: 4 | CP3: 4 | CQ3: 1 | CR3: 4 | CS3: 4 | CT3: 4 | CU3: 4 | CV3: 4 | CW3: 4 | CX3: 4 | CY3: 4 | CZ3: 4 | DA3: 4 | DB3: 4 | DC3: 4 | DD3: 4 | DE3: 4 | DF3: 1 | DG3: 4 | DH3: 4 | DI3: 4 | DJ3: 4 | DK3: 4 | DL3: 4 | DM3: 4 | DN3: 1 | DO3: 4 | DP3: 4 | DQ3: 4 | DR3: 4 | DS3: 4 | DT3: 4 | DU3: Johnson et al. 2008
A4: HE-SD3 | B4: Hadean Earth | C4: Silent Experiment | D4: Miller spark discharge apparatus + aspirator device, CH4 (200 torr), NH3 (200 torr), H2 (100 torr), 500 mL H2O | E4: 1 | F4: 4 | G4: 1 | H4: 1 | I4: 4 | J4: 1 | K4: 4 | L4: 1 | M4: 1 | N4: 4 | O4: 2 | P4: 4 | Q4: 4 | R4: 4 | S4: 4 | T4: 4 | U4: 1 | V4: 2 | W4: 4 | X4: 4 | Y4: 4 | Z4: 4 | AA4: 4 | AB4: 4 | AC4: 4 | AD4: 4 | AE4: 4 | AF4: 2 | AG4: 1 | AH4: 1 | AI4: 4 | AJ4: 1 | AK4: 1 | AL4: 1 | AM4: 1 | AN4: 4 | AO4: 4 | AP4: 4 | AQ4: 4 | AR4: 4 | AS4: 2 | AT4: 4 | AU4: 4 | AV4: 2 | AW4: 4 | AX4: 4 | AY4: 4 | AZ4: 4 | BA4: 4 | BB4: 4 | BC4: 4 | BD4: 4 | BE4: 2 | BF4: 1 | BG4: 1 | BH4: 4 | BI4: 4 | BJ4: 4 | BK4: 2 | BL4: 4 | BM4: 4 | BN4: 4 | BO4: 4 | BP4: 4 | BQ4: 4 | BR4: 4 | BS4: 4 | BT4: 4 | BU4: 4 | BV4: 4 | BW4: 1 | BX4: 1 | BY4: 4 | BZ4: 4 | CA4: 4 | CB4: 4 | CC4: 4 | CD4: 4 | CE4: 4 | CF4: 4 | CG4: 4 | CH4: 4 | CI4: 4 | CJ4: 4 | CK4: 2 | CL4: 4 | CM4: 4 | CN4: 4 | CO4: 4 | CP4: 4 | CQ4: 2 | CR4: 4 | CS4: 4 | CT4: 4 | CU4: 4 | CV4: 4 | CW4: 4 | CX4: 4 | CY4: 4 | CZ4: 4 | DA4: 4 | DB4: 4 | DC4: 4 | DD4: 4 | DE4: 4 | DF4: 2 | DG4: 4 | DH4: 4 | DI4: 4 | DJ4: 4 | DK4: 4 | DL4: 4 | DM4: 4 | DN4: 2 | DO4: 4 | DP4: 4 | DQ4: 4 | DR4: 4 | DS4: 4 | DT4: 4 | DU4: Johnson et al. 2008
A5: HE-SD4 | B5: Hadean Earth | C5: Hydrogen Sulfide Experiment | D5: Miller spark discharge 5-L apparatus (tesla coils), CH4/H2S/NH3/CO2 mixture (258 mmHg/100 mmHg/250 mmHg/87 mmHg), 300 mL H2O (boiled), 3 days | E5: 1 | F5: 4 | G5: 1 | H5: 1 | I5: 4 | J5: 1 | K5: 4 | L5: 1 | M5: 1 | N5: 4 | O5: 1 | P5: 4 | Q5: 4 | R5: 1 | S5: 1 | T5: 1 | U5: 4 | V5: 4 | W5: 4 | X5: 4 | Y5: 1 | Z5: 4 | AA5: 4 | AB5: 4 | AC5: 4 | AD5: 4 | AE5: 4 | AF5: 1 | AG5: 1 | AH5: 1 | AI5: 4 | AJ5: 1 | AK5: 1 | AL5: 4 | AM5: 4 | AN5: 1 | AO5: 4 | AP5: 4 | AQ5: 4 | AR5: 4 | AS5: 4 | AT5: 4 | AU5: 4 | AV5: 4 | AW5: 4 | AX5: 4 | AY5: 4 | AZ5: 4 | BA5: 1 | BB5: 1 | BC5: 4 | BD5: 4 | BE5: 1 | BF5: 1 | BG5: 1 | BH5: 4 | BI5: 4 | BJ5: 4 | BK5: 4 | BL5: 4 | BM5: 4 | BN5: 4 | BO5: 4 | BP5: 4 | BQ5: 4 | BR5: 4 | BS5: 4 | BT5: 4 | BU5: 4 | BV5: 4 | BW5: 1 | BX5: 1 | BY5: 4 | BZ5: 4 | CA5: 4 | CB5: 4 | CC5: 1 | CD5: 1 | CE5: 4 | CF5: 1 | CG5: 1 | CH5: 4 | CI5: 4 | CJ5: 4 | CK5: 4 | CL5: 4 | CM5: 4 | CN5: 4 | CO5: 4 | CP5: 4 | CQ5: 4 | CR5: 4 | CS5: 4 | CT5: 4 | CU5: 4 | CV5: 4 | CW5: 1 | CX5: 4 | CY5: 4 | CZ5: 1 | DA5: 4 | DB5: 4 | DC5: 4 | DD5: 4 | DE5: 4 | DF5: 4 | DG5: 4 | DH5: 4 | DI5: 4 | DJ5: 4 | DK5: 4 | DL5: 4 | DM5: 4 | DN5: 4 | DO5: 4 | DP5: 4 | DQ5: 4 | DR5: 4 | DS5: 4 | DT5: 4 | DU5: Parker et al. 2011
A6: HE-SD5 | B6: Hadean Earth | C6: Cyanamide Experiment | D6: Miller Cyanamide spark discharge (tesla coils), 250 mL H20, 300 mmHg CH4, 250 mmHg NH3, addition of cyanamide (3.3-4.4 mg in water) at different intervals | E6: 1 | F6: 4 | G6: 1 | H6: 1 | I6: 4 | J6: 1 | K6: 4 | L6: 1 | M6: 1 | N6: 4 | O6: 3 | P6: 4 | Q6: 4 | R6: 4 | S6: 1 | T6: 1 | U6: 4 | V6: 4 | W6: 4 | X6: 4 | Y6: 4 | Z6: 4 | AA6: 4 | AB6: 4 | AC6: 4 | AD6: 4 | AE6: 4 | AF6: 1 | AG6: 1 | AH6: 1 | AI6: 4 | AJ6: 1 | AK6: 3 | AL6: 4 | AM6: 4 | AN6: 4 | AO6: 4 | AP6: 4 | AQ6: 4 | AR6: 4 | AS6: 4 | AT6: 4 | AU6: 4 | AV6: 4 | AW6: 4 | AX6: 4 | AY6: 4 | AZ6: 4 | BA6: 4 | BB6: 4 | BC6: 1 | BD6: 1 | BE6: 4 | BF6: 1 | BG6: 1 | BH6: 4 | BI6: 4 | BJ6: 4 | BK6: 4 | BL6: 4 | BM6: 4 | BN6: 4 | BO6: 4 | BP6: 4 | BQ6: 4 | BR6: 4 | BS6: 4 | BT6: 4 | BU6: 4 | BV6: 4 | BW6: 1 | BX6: 1 | BY6: 4 | BZ6: 4 | CA6: 4 | CB6: 4 | CC6: 4 | CD6: 4 | CE6: 4 | CF6: 4 | CG6: 4 | CH6: 4 | CI6: 4 | CJ6: 4 | CK6: 4 | CL6: 4 | CM6: 4 | CN6: 4 | CO6: 4 | CP6: 4 | CQ6: 4 | CR6: 4 | CS6: 4 | CT6: 4 | CU6: 4 | CV6: 4 | CW6: 4 | CX6: 1 | CY6: 1 | CZ6: 4 | DA6: 4 | DB6: 4 | DC6: 4 | DD6: 4 | DE6: 4 | DF6: 4 | DG6: 4 | DH6: 4 | DI6: 4 | DJ6: 4 | DK6: 4 | DL6: 4 | DM6: 4 | DN6: 4 | DO6: 4 | DP6: 4 | DQ6: 4 | DR6: 4 | DS6: 4 | DT6: 4 | DU6: Parker et al. 2014
A7: HEA-PR1 | B7: Hadean Earth | C7: Atmosphere | D7: Proton irradiation, 1.58-2.5 MeV, 1-2 h, N2/CO2/CH4 mixture (350 torr/350 torr/0), 5 mL water | E7: 2 | F7: 4 | G7: 4 | H7: 4 | I7: 2 | J7: 2 | K7: 4 | L7: 4 | M7: 4 | N7: 2 | O7: 4 | P7: 4 | Q7: 4 | R7: 4 | S7: 4 | T7: 4 | U7: 2 | V7: 4 | W7: 4 | X7: 4 | Y7: 2 | Z7: 4 | AA7: 4 | AB7: 4 | AC7: 4 | AD7: 4 | AE7: 4 | AF7: 2 | AG7: 4 | AH7: 4 | AI7: 4 | AJ7: 2 | AK7: 4 | AL7: 4 | AM7: 4 | AN7: 2 | AO7: 4 | AP7: 4 | AQ7: 4 | AR7: 4 | AS7: 4 | AT7: 4 | AU7: 4 | AV7: 4 | AW7: 4 | AX7: 4 | AY7: 4 | AZ7: 4 | BA7: 4 | BB7: 4 | BC7: 4 | BD7: 4 | BE7: 2 | BF7: 4 | BG7: 4 | BH7: 4 | BI7: 4 | BJ7: 4 | BK7: 4 | BL7: 4 | BM7: 4 | BN7: 4 | BO7: 4 | BP7: 4 | BQ7: 4 | BR7: 4 | BS7: 4 | BT7: 4 | BU7: 4 | BV7: 4 | BW7: 4 | BX7: 4 | BY7: 2 | BZ7: 4 | CA7: 4 | CB7: 4 | CC7: 4 | CD7: 4 | CE7: 2 | CF7: 4 | CG7: 4 | CH7: 4 | CI7: 4 | CJ7: 4 | CK7: 4 | CL7: 4 | CM7: 4 | CN7: 4 | CO7: 4 | CP7: 4 | CQ7: 2 | CR7: 4 | CS7: 4 | CT7: 4 | CU7: 4 | CV7: 4 | CW7: 2 | CX7: 4 | CY7: 4 | CZ7: 2 | DA7: 4 | DB7: 4 | DC7: 4 | DD7: 4 | DE7: 4 | DF7: 4 | DG7: 4 | DH7: 4 | DI7: 4 | DJ7: 4 | DK7: 4 | DL7: 4 | DM7: 4 | DN7: 2 | DO7: 4 | DP7: 4 | DQ7: 2 | DR7: 4 | DS7: 4 | DT7: 4 | DU7: Kobayashi et al. 2023
A8: HEA-PR2 | B8: Hadean Earth | C8: Atmosphere | D8: Proton irradiation, 1.58-2.5 MeV, 1-2 h, N2/CO2/CH4 mixture (350 torr/346.5 torr/3.5 torr), 5 mL water | E8: 2 | F8: 4 | G8: 4 | H8: 4 | I8: 2 | J8: 2 | K8: 4 | L8: 4 | M8: 4 | N8: 2 | O8: 4 | P8: 4 | Q8: 4 | R8: 4 | S8: 4 | T8: 4 | U8: 2 | V8: 4 | W8: 4 | X8: 4 | Y8: 2 | Z8: 4 | AA8: 4 | AB8: 4 | AC8: 4 | AD8: 4 | AE8: 4 | AF8: 2 | AG8: 4 | AH8: 4 | AI8: 4 | AJ8: 2 | AK8: 4 | AL8: 4 | AM8: 4 | AN8: 2 | AO8: 4 | AP8: 4 | AQ8: 4 | AR8: 4 | AS8: 4 | AT8: 4 | AU8: 4 | AV8: 4 | AW8: 4 | AX8: 4 | AY8: 4 | AZ8: 4 | BA8: 4 | BB8: 4 | BC8: 4 | BD8: 4 | BE8: 2 | BF8: 4 | BG8: 4 | BH8: 4 | BI8: 4 | BJ8: 4 | BK8: 4 | BL8: 4 | BM8: 4 | BN8: 4 | BO8: 4 | BP8: 4 | BQ8: 4 | BR8: 4 | BS8: 4 | BT8: 4 | BU8: 4 | BV8: 4 | BW8: 4 | BX8: 4 | BY8: 2 | BZ8: 4 | CA8: 4 | CB8: 4 | CC8: 4 | CD8: 4 | CE8: 2 | CF8: 4 | CG8: 4 | CH8: 4 | CI8: 4 | CJ8: 4 | CK8: 4 | CL8: 4 | CM8: 4 | CN8: 4 | CO8: 4 | CP8: 4 | CQ8: 2 | CR8: 4 | CS8: 4 | CT8: 4 | CU8: 4 | CV8: 4 | CW8: 2 | CX8: 4 | CY8: 4 | CZ8: 2 | DA8: 4 | DB8: 4 | DC8: 4 | DD8: 4 | DE8: 4 | DF8: 4 | DG8: 4 | DH8: 4 | DI8: 4 | DJ8: 4 | DK8: 4 | DL8: 4 | DM8: 4 | DN8: 2 | DO8: 4 | DP8: 4 | DQ8: 2 | DR8: 4 | DS8: 4 | DT8: 4 | DU8: Kobayashi et al. 2023
A9: HEA-PR3 | B9: Hadean Earth | C9: Atmosphere | D9: Proton irradiation, 1.58-2.5 MeV, 1-2 h, N2/CO2/CH4 mixture (350 torr/343 torr/7 torr), 5 mL water | E9: 1 | F9: 4 | G9: 4 | H9: 4 | I9: 3 | J9: 2 | K9: 4 | L9: 4 | M9: 4 | N9: 2 | O9: 4 | P9: 4 | Q9: 4 | R9: 4 | S9: 4 | T9: 4 | U9: 2 | V9: 4 | W9: 4 | X9: 4 | Y9: 2 | Z9: 4 | AA9: 4 | AB9: 4 | AC9: 4 | AD9: 4 | AE9: 4 | AF9: 2 | AG9: 4 | AH9: 4 | AI9: 4 | AJ9: 2 | AK9: 4 | AL9: 4 | AM9: 4 | AN9: 2 | AO9: 4 | AP9: 4 | AQ9: 4 | AR9: 4 | AS9: 4 | AT9: 4 | AU9: 4 | AV9: 4 | AW9: 4 | AX9: 4 | AY9: 4 | AZ9: 4 | BA9: 4 | BB9: 4 | BC9: 4 | BD9: 4 | BE9: 2 | BF9: 4 | BG9: 4 | BH9: 4 | BI9: 4 | BJ9: 4 | BK9: 4 | BL9: 4 | BM9: 4 | BN9: 4 | BO9: 4 | BP9: 4 | BQ9: 4 | BR9: 4 | BS9: 4 | BT9: 4 | BU9: 4 | BV9: 4 | BW9: 4 | BX9: 4 | BY9: 2 | BZ9: 4 | CA9: 4 | CB9: 4 | CC9: 4 | CD9: 4 | CE9: 2 | CF9: 4 | CG9: 4 | CH9: 4 | CI9: 4 | CJ9: 4 | CK9: 4 | CL9: 4 | CM9: 4 | CN9: 4 | CO9: 4 | CP9: 4 | CQ9: 2 | CR9: 4 | CS9: 4 | CT9: 4 | CU9: 4 | CV9: 4 | CW9: 2 | CX9: 4 | CY9: 4 | CZ9: 2 | DA9: 4 | DB9: 4 | DC9: 4 | DD9: 4 | DE9: 4 | DF9: 4 | DG9: 4 | DH9: 4 | DI9: 4 | DJ9: 4 | DK9: 4 | DL9: 4 | DM9: 4 | DN9: 2 | DO9: 4 | DP9: 4 | DQ9: 2 | DR9: 4 | DS9: 4 | DT9: 4 | DU9: Kobayashi et al. 2023
A10: HEA-PR4 | B10: Hadean Earth | C10: Atmosphere | D10: Proton irradiation, 1.58-2.5 MeV, 1-2 h, N2/CO2/CH4 mixture (350 torr/336 torr/14 torr), 5 mL water | E10: 1 | F10: 4 | G10: 4 | H10: 4 | I10: 3 | J10: 1 | K10: 4 | L10: 4 | M10: 4 | N10: 1 | O10: 4 | P10: 4 | Q10: 4 | R10: 4 | S10: 4 | T10: 4 | U10: 2 | V10: 4 | W10: 4 | X10: 4 | Y10: 2 | Z10: 4 | AA10: 4 | AB10: 4 | AC10: 4 | AD10: 4 | AE10: 4 | AF10: 1 | AG10: 4 | AH10: 4 | AI10: 4 | AJ10: 2 | AK10: 4 | AL10: 4 | AM10: 4 | AN10: 2 | AO10: 4 | AP10: 4 | AQ10: 4 | AR10: 4 | AS10: 4 | AT10: 4 | AU10: 4 | AV10: 4 | AW10: 4 | AX10: 4 | AY10: 4 | AZ10: 4 | BA10: 4 | BB10: 4 | BC10: 4 | BD10: 4 | BE10: 2 | BF10: 4 | BG10: 4 | BH10: 4 | BI10: 4 | BJ10: 4 | BK10: 4 | BL10: 4 | BM10: 4 | BN10: 4 | BO10: 4 | BP10: 4 | BQ10: 4 | BR10: 4 | BS10: 4 | BT10: 4 | BU10: 4 | BV10: 4 | BW10: 4 | BX10: 4 | BY10: 2 | BZ10: 4 | CA10: 4 | CB10: 4 | CC10: 4 | CD10: 4 | CE10: 2 | CF10: 4 | CG10: 4 | CH10: 4 | CI10: 4 | CJ10: 4 | CK10: 4 | CL10: 4 | CM10: 4 | CN10: 4 | CO10: 4 | CP10: 4 | CQ10: 2 | CR10: 4 | CS10: 4 | CT10: 4 | CU10: 4 | CV10: 4 | CW10: 2 | CX10: 4 | CY10: 4 | CZ10: 2 | DA10: 4 | DB10: 4 | DC10: 4 | DD10: 4 | DE10: 4 | DF10: 4 | DG10: 4 | DH10: 4 | DI10: 4 | DJ10: 4 | DK10: 4 | DL10: 4 | DM10: 4 | DN10: 2 | DO10: 4 | DP10: 4 | DQ10: 2 | DR10: 4 | DS10: 4 | DT10: 4 | DU10: Kobayashi et al. 2023
A11: HEA-PR5 | B11: Hadean Earth | C11: Atmosphere | D11: Proton irradiation, 1.58-2.5 MeV, 1-2 h, N2/CO2/CH4 mixture (350 torr/329 torr/21 torr), 5 mL water | E11: 1 | F11: 4 | G11: 4 | H11: 4 | I11: 3 | J11: 1 | K11: 4 | L11: 4 | M11: 4 | N11: 1 | O11: 4 | P11: 4 | Q11: 4 | R11: 4 | S11: 4 | T11: 4 | U11: 2 | V11: 4 | W11: 4 | X11: 4 | Y11: 2 | Z11: 4 | AA11: 4 | AB11: 4 | AC11: 4 | AD11: 4 | AE11: 4 | AF11: 1 | AG11: 4 | AH11: 4 | AI11: 4 | AJ11: 2 | AK11: 4 | AL11: 4 | AM11: 4 | AN11: 2 | AO11: 4 | AP11: 4 | AQ11: 4 | AR11: 4 | AS11: 4 | AT11: 4 | AU11: 4 | AV11: 4 | AW11: 4 | AX11: 4 | AY11: 4 | AZ11: 4 | BA11: 4 | BB11: 4 | BC11: 4 | BD11: 4 | BE11: 2 | BF11: 4 | BG11: 4 | BH11: 4 | BI11: 4 | BJ11: 4 | BK11: 4 | BL11: 4 | BM11: 4 | BN11: 4 | BO11: 4 | BP11: 4 | BQ11: 4 | BR11: 4 | BS11: 4 | BT11: 4 | BU11: 4 | BV11: 4 | BW11: 4 | BX11: 4 | BY11: 2 | BZ11: 4 | CA11: 4 | CB11: 4 | CC11: 4 | CD11: 4 | CE11: 2 | CF11: 4 | CG11: 4 | CH11: 4 | CI11: 4 | CJ11: 4 | CK11: 4 | CL11: 4 | CM11: 4 | CN11: 4 | CO11: 4 | CP11: 4 | CQ11: 2 | CR11: 4 | CS11: 4 | CT11: 4 | CU11: 4 | CV11: 4 | CW11: 2 | CX11: 4 | CY11: 4 | CZ11: 2 | DA11: 4 | DB11: 4 | DC11: 4 | DD11: 4 | DE11: 4 | DF11: 4 | DG11: 4 | DH11: 4 | DI11: 4 | DJ11: 4 | DK11: 4 | DL11: 4 | DM11: 4 | DN11: 2 | DO11: 4 | DP11: 4 | DQ11: 2 | DR11: 4 | DS11: 4 | DT11: 4 | DU11: Kobayashi et al. 2023
A12: HEA-PR6 | B12: Hadean Earth | C12: Atmosphere | D12: Proton irradiation, 1.58-2.5 MeV, 1-2 h, N2/CO2/CH4 mixture (350 torr/315 torr/35 torr), 5 mL water | E12: 1 | F12: 4 | G12: 4 | H12: 4 | I12: 3 | J12: 1 | K12: 4 | L12: 4 | M12: 4 | N12: 1 | O12: 4 | P12: 4 | Q12: 4 | R12: 4 | S12: 4 | T12: 4 | U12: 1 | V12: 4 | W12: 4 | X12: 4 | Y12: 2 | Z12: 4 | AA12: 4 | AB12: 4 | AC12: 4 | AD12: 4 | AE12: 4 | AF12: 1 | AG12: 4 | AH12: 4 | AI12: 4 | AJ12: 2 | AK12: 4 | AL12: 4 | AM12: 4 | AN12: 2 | AO12: 4 | AP12: 4 | AQ12: 4 | AR12: 4 | AS12: 4 | AT12: 4 | AU12: 4 | AV12: 4 | AW12: 4 | AX12: 4 | AY12: 4 | AZ12: 4 | BA12: 4 | BB12: 4 | BC12: 4 | BD12: 4 | BE12: 2 | BF12: 4 | BG12: 4 | BH12: 4 | BI12: 4 | BJ12: 4 | BK12: 4 | BL12: 4 | BM12: 4 | BN12: 4 | BO12: 4 | BP12: 4 | BQ12: 4 | BR12: 4 | BS12: 4 | BT12: 4 | BU12: 4 | BV12: 4 | BW12: 4 | BX12: 4 | BY12: 2 | BZ12: 4 | CA12: 4 | CB12: 4 | CC12: 4 | CD12: 4 | CE12: 2 | CF12: 4 | CG12: 4 | CH12: 4 | CI12: 4 | CJ12: 4 | CK12: 4 | CL12: 4 | CM12: 4 | CN12: 4 | CO12: 4 | CP12: 4 | CQ12: 2 | CR12: 4 | CS12: 4 | CT12: 4 | CU12: 4 | CV12: 4 | CW12: 2 | CX12: 4 | CY12: 4 | CZ12: 2 | DA12: 4 | DB12: 4 | DC12: 4 | DD12: 4 | DE12: 4 | DF12: 4 | DG12: 4 | DH12: 4 | DI12: 4 | DJ12: 4 | DK12: 4 | DL12: 4 | DM12: 4 | DN12: 2 | DO12: 4 | DP12: 4 | DQ12: 2 | DR12: 4 | DS12: 4 | DT12: 4 | DU12: Kobayashi et al. 2023
A13: HEA-PR7 | B13: Hadean Earth | C13: Atmosphere | D13: Proton irradiation, 1.58-2.5 MeV, 1-2 h, N2/CO2/CH4 mixture (350 torr/280 torr/70 torr), 5 mL water | E13: 1 | F13: 4 | G13: 4 | H13: 4 | I13: 3 | J13: 1 | K13: 4 | L13: 4 | M13: 4 | N13: 1 | O13: 4 | P13: 4 | Q13: 4 | R13: 4 | S13: 4 | T13: 4 | U13: 1 | V13: 4 | W13: 4 | X13: 4 | Y13: 2 | Z13: 4 | AA13: 4 | AB13: 4 | AC13: 4 | AD13: 4 | AE13: 4 | AF13: 1 | AG13: 4 | AH13: 4 | AI13: 4 | AJ13: 2 | AK13: 4 | AL13: 4 | AM13: 4 | AN13: 2 | AO13: 4 | AP13: 4 | AQ13: 4 | AR13: 4 | AS13: 4 | AT13: 4 | AU13: 4 | AV13: 4 | AW13: 4 | AX13: 4 | AY13: 4 | AZ13: 4 | BA13: 4 | BB13: 4 | BC13: 4 | BD13: 4 | BE13: 2 | BF13: 4 | BG13: 4 | BH13: 4 | BI13: 4 | BJ13: 4 | BK13: 4 | BL13: 4 | BM13: 4 | BN13: 4 | BO13: 4 | BP13: 4 | BQ13: 4 | BR13: 4 | BS13: 4 | BT13: 4 | BU13: 4 | BV13: 4 | BW13: 4 | BX13: 4 | BY13: 2 | BZ13: 4 | CA13: 4 | CB13: 4 | CC13: 4 | CD13: 4 | CE13: 2 | CF13: 4 | CG13: 4 | CH13: 4 | CI13: 4 | CJ13: 4 | CK13: 4 | CL13: 4 | CM13: 4 | CN13: 4 | CO13: 4 | CP13: 4 | CQ13: 2 | CR13: 4 | CS13: 4 | CT13: 4 | CU13: 4 | CV13: 4 | CW13: 2 | CX13: 4 | CY13: 4 | CZ13: 2 | DA13: 4 | DB13: 4 | DC13: 4 | DD13: 4 | DE13: 4 | DF13: 4 | DG13: 4 | DH13: 4 | DI13: 4 | DJ13: 4 | DK13: 4 | DL13: 4 | DM13: 4 | DN13: 2 | DO13: 4 | DP13: 4 | DQ13: 2 | DR13: 4 | DS13: 4 | DT13: 4 | DU13: Kobayashi et al. 2023
... A27: HEA-SD9 | B27: Hadean Earth | C27: Atmosphere | D27: Spark discharge (tesla coil, 1mon on/1 min off, 24h), N2/CO2/CH4 mixture (350 torr/0/350 torr), 5 mL water | E27: 1 | F27: 4 | G27: 4 | H27: 4 | I27: 3 | J27: 1 | K27: 4 | L27: 4 | M27: 4 | N27: 1 | O27: 4 | P27: 4 | Q27: 4 | R27: 4 | S27: 4 | T27: 4 | U27: 1 | V27: 4 | W27: 4 | X27: 4 | Y27: 2 | Z27: 4 | AA27: 4 | AB27: 4 | AC27: 4 | AD27: 4 | AE27: 4 | AF27: 1 | AG27: 4 | AH27: 4 | AI27: 4 | AJ27: 1 | AK27: 4 | AL27: 4 | AM27: 4 | AN27: 2 | AO27: 4 | AP27: 4 | AQ27: 4 | AR27: 4 | AS27: 4 | AT27: 4 | AU27: 4 | AV27: 4 | AW27: 4 | AX27: 4 | AY27: 4 | AZ27: 4 | BA27: 4 | BB27: 4 | BC27: 4 | BD27: 4 | BE27: 2 | BF27: 4 | BG27: 4 | BH27: 4 | BI27: 4 | BJ27: 4 | BK27: 4 | BL27: 4 | BM27: 4 | BN27: 4 | BO27: 4 | BP27: 4 | BQ27: 4 | BR27: 4 | BS27: 4 | BT27: 4 | BU27: 4 | BV27: 4 | BW27: 4 | BX27: 4 | BY27: 2 | BZ27: 4 | CA27: 4 | CB27: 4 | CC27: 4 | CD27: 4 | CE27: 2 | CF27: 4 | CG27: 4 | CH27: 4 | CI27: 4 | CJ27: 4 | CK27: 4 | CL27: 4 | CM27: 4 | CN27: 4 | CO27: 4 | CP27: 4 | CQ27: 2 | CR27: 4 | CS27: 4 | CT27: 4 | CU27: 4 | CV27: 4 | CW27: 2 | CX27: 4 | CY27: 4 | CZ27: 2 | DA27: 4 | DB27: 4 | DC27: 4 | DD27: 4 | DE27: 4 | DF27: 4 | DG27: 4 | DH27: 4 | DI27: 4 | DJ27: 4 | DK27: 4 | DL27: 4 | DM27: 4 | DN27: 2 | DO27: 4 | DP27: 4 | DQ27: 2 | DR27: 4 | DS27: 4 | DT27: 4 | DU27: Kobayashi et al. 2023
A28: EUR-CN1 | B28: Europa | D28: 0.1 M NH4CN, 25 years storage at -78°C | E28: 1 | F28: 4 | G28: 1 | H28: 1 | I28: 4 | J28: 4 | K28: 4 | L28: 4 | M28: 5 | N28: 4 | O28: 4 | P28: 4 | Q28: 4 | R28: 4 | S28: 1 | T28: 1 | U28: 4 | V28: 4 | W28: 4 | X28: 4 | Y28: 4 | Z28: 4 | AA28: 4 | AB28: 4 | AC28: 4 | AD28: 4 | AE28: 4 | AF28: 4 | AG28: 4 | AH28: 4 | AI28: 4 | AJ28: 4 | AK28: 4 | AL28: 4 | AM28: 4 | AN28: 4 | AO28: 4 | AP28: 4 | AQ28: 4 | AR28: 4 | AS28: 4 | AT28: 4 | AU28: 4 | AV28: 4 | AW28: 4 | AX28: 4 | AY28: 4 | AZ28: 4 | BA28: 4 | BB28: 4 | BC28: 4 | BD28: 4 | BE28: 4 | BF28: 4 | BG28: 4 | BH28: 4 | BI28: 4 | BJ28: 4 | BK28: 4 | BL28: 4 | BM28: 4 | BN28: 4 | BO28: 4 | BP28: 4 | BQ28: 4 | BR28: 4 | BS28: 4 | BT28: 4 | BU28: 4 | BV28: 4 | BW28: 4 | BX28: 4 | BY28: 4 | BZ28: 4 | CA28: 4 | CB28: 4 | CC28: 4 | CD28: 4 | CE28: 4 | CF28: 4 | CG28: 4 | CH28: 4 | CI28: 4 | CJ28: 4 | CK28: 4 | CL28: 4 | CM28: 4 | CN28: 4 | CO28: 4 | CP28: 4 | CQ28: 4 | CR28: 4 | CS28: 4 | CT28: 4 | CU28: 4 | CV28: 4 | CW28: 4 | CX28: 4 | CY28: 4 | CZ28: 4 | DA28: 4 | DB28: 4 | DC28: 4 | DD28: 4 | DE28: 4 | DF28: 4 | DG28: 4 | DH28: 4 | DI28: 4 | DJ28: 4 | DK28: 4 | DL28: 4 | DM28: 4 | DN28: 4 | DO28: 4 | DP28: 4 | DQ28: 4 | DR28: 4 | DS28: 4 | DT28: 4 | DU28: Levy & Miller, 2000
A29: EUR-CN2 | B29: Europa | D29: 0.1 M NH4CN, 25 years storage at -20°C | E29: 1 | F29: 4 | G29: 1 | H29: 1 | I29: 4 | J29: 4 | K29: 4 | L29: 4 | M29: 5 | N29: 4 | O29: 4 | P29: 4 | Q29: 4 | R29: 4 | S29: 1 | T29: 1 | U29: 4 | V29: 4 | W29: 4 | X29: 4 | Y29: 4 | Z29: 4 | AA29: 4 | AB29: 4 | AC29: 4 | AD29: 4 | AE29: 4 | AF29: 4 | AG29: 4 | AH29: 4 | AI29: 4 | AJ29: 4 | AK29: 4 | AL29: 4 | AM29: 4 | AN29: 4 | AO29: 4 | AP29: 4 | AQ29: 4 | AR29: 4 | AS29: 4 | AT29: 4 | AU29: 4 | AV29: 4 | AW29: 4 | AX29: 4 | AY29: 4 | AZ29: 4 | BA29: 4 | BB29: 4 | BC29: 4 | BD29: 4 | BE29: 4 | BF29: 4 | BG29: 4 | BH29: 4 | BI29: 4 | BJ29: 4 | BK29: 4 | BL29: 4 | BM29: 4 | BN29: 4 | BO29: 4 | BP29: 4 | BQ29: 4 | BR29: 4 | BS29: 4 | BT29: 4 | BU29: 4 | BV29: 4 | BW29: 4 | BX29: 4 | BY29: 4 | BZ29: 4 | CA29: 4 | CB29: 4 | CC29: 4 | CD29: 4 | CE29: 4 | CF29: 4 | CG29: 4 | CH29: 4 | CI29: 4 | CJ29: 4 | CK29: 4 | CL29: 4 | CM29: 4 | CN29: 4 | CO29: 4 | CP29: 4 | CQ29: 4 | CR29: 4 | CS29: 4 | CT29: 4 | CU29: 4 | CV29: 4 | CW29: 4 | CX29: 4 | CY29: 4 | CZ29: 4 | DA29: 4 | DB29: 4 | DC29: 4 | DD29: 4 | DE29: 4 | DF29: 4 | DG29: 4 | DH29: 4 | DI29: 4 | DJ29: 4 | DK29: 4 | DL29: 4 | DM29: 4 | DN29: 4 | DO29: 4 | DP29: 4 | DQ29: 4 | DR29: 4 | DS29: 4 | DT29: 4 | DU29: Levy & Miller, 2000
A30: EUR-CN3 | B30: Europa | D30: 0.1 M NH4CN, 2 months storage at -20°C | E30: 1 | F30: 4 | G30: 1 | H30: 1 | I30: 4 | J30: 4 | K30: 4 | L30: 4 | M30: 5 | N30: 4 | O30: 4 | P30: 4 | Q30: 4 | R30: 4 | S30: 1 | T30: 1 | U30: 4 | V30: 4 | W30: 4 | X30: 4 | Y30: 4 | Z30: 4 | AA30: 4 | AB30: 4 | AC30: 4 | AD30: 4 | AE30: 4 | AF30: 4 | AG30: 4 | AH30: 4 | AI30: 4 | AJ30: 4 | AK30: 4 | AL30: 4 | AM30: 4 | AN30: 4 | AO30: 4 | AP30: 4 | AQ30: 4 | AR30: 4 | AS30: 4 | AT30: 4 | AU30: 4 | AV30: 4 | AW30: 4 | AX30: 4 | AY30: 4 | AZ30: 4 | BA30: 4 | BB30: 4 | BC30: 4 | BD30: 4 | BE30: 4 | BF30: 4 | BG30: 4 | BH30: 4 | BI30: 4 | BJ30: 4 | BK30: 4 | BL30: 4 | BM30: 4 | BN30: 4 | BO30: 4 | BP30: 4 | BQ30: 4 | BR30: 4 | BS30: 4 | BT30: 4 | BU30: 4 | BV30: 4 | BW30: 4 | BX30: 4 | BY30: 4 | BZ30: 4 | CA30: 4 | CB30: 4 | CC30: 4 | CD30: 4 | CE30: 4 | CF30: 4 | CG30: 4 | CH30: 4 | CI30: 4 | CJ30: 4 | CK30: 4 | CL30: 4 | CM30: 4 | CN30: 4 | CO30: 4 | CP30: 4 | CQ30: 4 | CR30: 4 | CS30: 4 | CT30: 4 | CU30: 4 | CV30: 4 | CW30: 4 | CX30: 4 | CY30: 4 | CZ30: 4 | DA30: 4 | DB30: 4 | DC30: 4 | DD30: 4 | DE30: 4 | DF30: 4 | DG30: 4 | DH30: 4 | DI30: 4 | DJ30: 4 | DK30: 4 | DL30: 4 | DM30: 4 | DN30: 4 | DO30: 4 | DP30: 4 | DQ30: 4 | DR30: 4 | DS30: 4 | DT30: 4 | DU30: Levy & Miller, 2000
A31: EUR-SD1 | B31: Europa | D31: Spark discharge, 5 years storage -20°C | E31: 1 | F31: 4 | G31: 1 | H31: 1 | I31: 4 | J31: 4 | K31: 4 | L31: 4 | M31: 5 | N31: 4 | O31: 4 | P31: 4 | Q31: 4 | R31: 4 | S31: 1 | T31: 1 | U31: 4 | V31: 4 | W31: 4 | X31: 4 | Y31: 4 | Z31: 4 | AA31: 4 | AB31: 4 | AC31: 4 | AD31: 4 | AE31: 4 | AF31: 4 | AG31: 4 | AH31: 4 | AI31: 4 | AJ31: 4 | AK31: 4 | AL31: 4 | AM31: 4 | AN31: 4 | AO31: 4 | AP31: 4 | AQ31: 4 | AR31: 4 | AS31: 4 | AT31: 4 | AU31: 4 | AV31: 4 | AW31: 4 | AX31: 4 | AY31: 4 | AZ31: 4 | BA31: 4 | BB31: 4 | BC31: 4 | BD31: 4 | BE31: 4 | BF31: 4 | BG31: 4 | BH31: 4 | BI31: 4 | BJ31: 4 | BK31: 4 | BL31: 4 | BM31: 4 | BN31: 4 | BO31: 4 | BP31: 4 | BQ31: 4 | BR31: 4 | BS31: 4 | BT31: 4 | BU31: 4 | BV31: 4 | BW31: 4 | BX31: 4 | BY31: 4 | BZ31: 4 | CA31: 4 | CB31: 4 | CC31: 4 | CD31: 4 | CE31: 4 | CF31: 4 | CG31: 4 | CH31: 4 | CI31: 4 | CJ31: 4 | CK31: 4 | CL31: 4 | CM31: 4 | CN31: 4 | CO31: 4 | CP31: 4 | CQ31: 4 | CR31: 4 | CS31: 4 | CT31: 4 | CU31: 4 | CV31: 4 | CW31: 4 | CX31: 4 | CY31: 4 | CZ31: 4 | DA31: 4 | DB31: 4 | DC31: 4 | DD31: 4 | DE31: 4 | DF31: 4 | DG31: 4 | DH31: 4 | DI31: 4 | DJ31: 4 | DK31: 4 | DL31: 4 | DM31: 4 | DN31: 4 | DO31: 4 | DP31: 4 | DQ31: 4 | DR31: 4 | DS31: 4 | DT31: 4 | DU31: Levy & Miller, 2000
A32: NOM-OC1 | B32: Noachian Mars | D32: Ordinary chondrite analogue [metallic Fe (100 mg) and Ni (10 mg), forsterite(200 mg)], heat-treated at 450C for 6h, shock experiment with NAHCO3 + N2, 1km/sec acceleration, 300C | E32: 1 | F32: 4 | G32: 4 | H32: 4 | I32: 2 | J32: 2 | K32: 2 | L32: 4 | M32: 4 | N32: 4 | O32: 4 | P32: 4 | Q32: 4 | R32: 4 | S32: 4 | T32: 4 | U32: 4 | V32: 4 | W32: 4 | X32: 4 | Y32: 4 | Z32: 4 | AA32: 4 | AB32: 4 | AC32: 4 | AD32: 4 | AE32: 4 | AF32: 2 | AG32: 4 | AH32: 4 | AI32: 4 | AJ32: 4 | AK32: 4 | AL32: 4 | AM32: 4 | AN32: 2 | AO32: 4 | AP32: 4 | AQ32: 4 | AR32: 4 | AS32: 4 | AT32: 4 | AU32: 4 | AV32: 4 | AW32: 4 | AX32: 4 | AY32: 4 | AZ32: 4 | BA32: 4 | BB32: 4 | BC32: 4 | BD32: 4 | BE32: 4 | BF32: 4 | BG32: 4 | BH32: 4 | BI32: 4 | BJ32: 4 | BK32: 4 | BL32: 4 | BM32: 4 | BN32: 4 | BO32: 4 | BP32: 4 | BQ32: 4 | BR32: 4 | BS32: 4 | BT32: 4 | BU32: 4 | BV32: 4 | BW32: 4 | BX32: 4 | BY32: 4 | BZ32: 4 | CA32: 4 | CB32: 4 | CC32: 4 | CD32: 4 | CE32: 4 | CF32: 4 | CG32: 4 | CH32: 4 | CI32: 4 | CJ32: 4 | CK32: 4 | CL32: 4 | CM32: 4 | CN32: 4 | CO32: 4 | CP32: 4 | CQ32: 4 | CR32: 4 | CS32: 4 | CT32: 4 | CU32: 4 | CV32: 4 | CW32: 4 | CX32: 4 | CY32: 4 | CZ32: 4 | DA32: 4 | DB32: 4 | DC32: 4 | DD32: 4 | DE32: 4 | DF32: 4 | DG32: 4 | DH32: 4 | DI32: 4 | DJ32: 4 | DK32: 4 | DL32: 4 | DM32: 4 | DN32: 4 | DO32: 4 | DP32: 4 | DQ32: 4 | DR32: 4 | DS32: 4 | DT32: 4 | DU32: Takeuchi et al. 2020
A33: NOM-IC1 | B33: Noachian Mars | D33: Iron chondrite analogue [metallic Fe (300 mg) and Ni (10 mg)], heat-treated at 450C for 6h, shock experiment with NAHCO3 + N2, 1km/sec acceleration, 300C | E33: 1 | F33: 4 | G33: 4 | H33: 4 | I33: 1 | J33: 2 | K33: 2 | L33: 4 | M33: 4 | N33: 4 | O33: 4 | P33: 4 | Q33: 4 | R33: 4 | S33: 4 | T33: 4 | U33: 4 | V33: 4 | W33: 4 | X33: 4 | Y33: 4 | Z33: 4 | AA33: 4 | AB33: 4 | AC33: 4 | AD33: 4 | AE33: 4 | AF33: 2 | AG33: 4 | AH33: 4 | AI33: 4 | AJ33: 4 | AK33: 4 | AL33: 4 | AM33: 4 | AN33: 2 | AO33: 4 | AP33: 4 | AQ33: 4 | AR33: 4 | AS33: 4 | AT33: 4 | AU33: 4 | AV33: 4 | AW33: 4 | AX33: 4 | AY33: 4 | AZ33: 4 | BA33: 4 | BB33: 4 | BC33: 4 | BD33: 4 | BE33: 4 | BF33: 4 | BG33: 4 | BH33: 4 | BI33: 4 | BJ33: 4 | BK33: 4 | BL33: 4 | BM33: 4 | BN33: 4 | BO33: 4 | BP33: 4 | BQ33: 4 | BR33: 4 | BS33: 4 | BT33: 4 | BU33: 4 | BV33: 4 | BW33: 4 | BX33: 4 | BY33: 4 | BZ33: 4 | CA33: 4 | CB33: 4 | CC33: 4 | CD33: 4 | CE33: 4 | CF33: 4 | CG33: 4 | CH33: 4 | CI33: 4 | CJ33: 4 | CK33: 4 | CL33: 4 | CM33: 4 | CN33: 4 | CO33: 4 | CP33: 4 | CQ33: 4 | CR33: 4 | CS33: 4 | CT33: 4 | CU33: 4 | CV33: 4 | CW33: 4 | CX33: 4 | CY33: 4 | CZ33: 4 | DA33: 4 | DB33: 4 | DC33: 4 | DD33: 4 | DE33: 4 | DF33: 4 | DG33: 4 | DH33: 4 | DI33: 4 | DJ33: 4 | DK33: 4 | DL33: 4 | DM33: 4 | DN33: 4 | DO33: 4 | DP33: 4 | DQ33: 4 | DR33: 4 | DS33: 4 | DT33: 4 | DU33: Takeuchi et al. 2020
A34: NOM-OC2 | B34: Noachian Mars | D34: Ordinary chondrite analogue [metallic Fe (100 mg) and Ni (10 mg), forsterite(200 mg)], heat-treated at 450C for 6h, shock experiment with NAHCO3 + N2 + 20 mmol/L NH3, 1km/sec acceleration, 300C | E34: 1 | F34: 4 | G34: 4 | H34: 4 | I34: 1 | J34: 2 | K34: 2 | L34: 4 | M34: 4 | N34: 4 | O34: 4 | P34: 4 | Q34: 4 | R34: 4 | S34: 4 | T34: 4 | U34: 4 | V34: 4 | W34: 4 | X34: 4 | Y34: 4 | Z34: 4 | AA34: 4 | AB34: 4 | AC34: 4 | AD34: 4 | AE34: 4 | AF34: 2 | AG34: 4 | AH34: 4 | AI34: 4 | AJ34: 4 | AK34: 4 | AL34: 4 | AM34: 4 | AN34: 2 | AO34: 4 | AP34: 4 | AQ34: 4 | AR34: 4 | AS34: 4 | AT34: 4 | AU34: 4 | AV34: 4 | AW34: 4 | AX34: 4 | AY34: 4 | AZ34: 4 | BA34: 4 | BB34: 4 | BC34: 4 | BD34: 4 | BE34: 4 | BF34: 4 | BG34: 4 | BH34: 4 | BI34: 4 | BJ34: 4 | BK34: 4 | BL34: 4 | BM34: 4 | BN34: 4 | BO34: 4 | BP34: 4 | BQ34: 4 | BR34: 4 | BS34: 4 | BT34: 4 | BU34: 4 | BV34: 4 | BW34: 4 | BX34: 4 | BY34: 4 | BZ34: 4 | CA34: 4 | CB34: 4 | CC34: 4 | CD34: 4 | CE34: 4 | CF34: 4 | CG34: 4 | CH34: 4 | CI34: 4 | CJ34: 4 | CK34: 4 | CL34: 4 | CM34: 4 | CN34: 4 | CO34: 4 | CP34: 4 | CQ34: 4 | CR34: 4 | CS34: 4 | CT34: 4 | CU34: 4 | CV34: 4 | CW34: 4 | CX34: 4 | CY34: 4 | CZ34: 4 | DA34: 4 | DB34: 4 | DC34: 4 | DD34: 4 | DE34: 4 | DF34: 4 | DG34: 4 | DH34: 4 | DI34: 4 | DJ34: 4 | DK34: 4 | DL34: 4 | DM34: 4 | DN34: 4 | DO34: 4 | DP34: 4 | DQ34: 4 | DR34: 4 | DS34: 4 | DT34: 4 | DU34: Takeuchi et al. 2020
